Workbook
Name INTERIM: [1]Interim!$A$3:$A$37

Sheet REGLES
B2: REGLES DE SAISIE DU FICHIER
H30: Renseigner les heures semaines par semaines sans tenir compte de majoration, … Renseigner le nombre d'heure au 1/4 d'heure prêt
B31: Renseigner le service suivant le menu déroulant prévu à cet effet
E32: Renseigner le temps restant au 31/12/ de l'année N-1
D36: Renseigner le temps de travail du salarié
F42: Gestion du compteur de l'année N-1
F43: Renseigner selon l'accord du salarié le % de ce compteur de l'année N-1 qui sera pris en congés. Le % payé sera la différence
F44: L'information est à mettre en colonne BN.
F46: Le type de majoration permet de conserver la règle et pour la partie "pris en congés", de faire le calcul déjà majoré pour le résultat
F48: Si les congés sont prises sur le compteur de l'année N-1, il faut venir indiquer la quantité prise dans la colonne BP
J71: Venir ici inscire pour chaque semaine, pour chaque service, si il s'agit de modulation (U) ou d'heures majorées (M)
J72: Cette décision est prise par la direction en fonction de l'accord 35h en vigueur ou de décisions ponctuelles
H95: Le calcul des heures sup avec ou sans majoration en fonction du choix du tableau ci-dessus semaine par semaine, service par service, est fait dans ce tableau
H96: NE RIEN ECRIRE EN MANUEL ICI
B117: RESULTAT
H122: SUR CE TABLEAU, LE RESULTAT DES HEURES RESTANT A ETRE PRISES POUR L'ANNEE N-1
H123: ET
H124: LE NOMBRE D'HEURE A PRENDRE POUR L'ANNEE N
H126: Si des heures sont payées durant l'année N, il faut les déduire dans la colonne ci-dessous (colonne BL) sans majoration
C161: EN CAS D'ARRET MALADIE
C162: Si arrêt 1 semaine : indiquer les heures théoriques
C163: Si arrêt de 2 semaine consécutives : noter le nombre d'heure contrat

Sheet paramètres
B2: horaires
C3: min | D3: max
B4: Production CE | C4: 39 | D4: 39
B5: Production | C5: 33 | D5: 41
B6: Logistique | C6: 39 | D6: 39
B9: Mise en forme
B11: vert | C11: 0 | D11: 120
B12: orange | C12: =D11 -> 120 | D12: 170
B13: rouge | C13: =D12 -> 170 | D13: 220
B14: noire | C14: =D13 -> 220

Sheet detail par semaine
F2: Heures faites | BG2: Heure théorique | DH2: Différentiel heure | FJ2: Majoration à 1,25 | HL2: Majoration à 1,5
DH3: 1 | FJ3: 1.25 | FK3: 43 | FL3: 74 | FM3: 86 | HL3: 1.5 | JO3: Total non majoré
C4: ='MODU 2025'!C7 -> Service | D4: ='MODU 2025'!D7 -> Contrat Base | F4: ='MODU 2025'!G7 -> S2 | G4: ='MODU 2025'!H7 -> S3 | H4: ='MODU 2025'!I7 -> S4 | I4: ='MODU 2025'!J7 -> S5 | J4: ='MODU 2025'!K7 -> S6 | K4: ='MODU 2025'!L7 -> S7 | L4: ='MODU 2025'!M7 -> S8 | M4: ='MODU 2025'!N7 -> S9 | ... BE4: ='MODU 2025'!BF7 -> S52+1 | BG4: ='MODU 2025'!G7 -> S2 | BH4: ='MODU 2025'!H7 -> S3 | BI4: ='MODU 2025'!I7 -> S4 | BJ4: ='MODU 2025'!J7 -> S5 | BK4: ='MODU 2025'!K7 -> S6 | BL4: ='MODU 2025'!L7 -> S7 | BM4: ='MODU 2025'!M7 -> S8 | BN4: ='MODU 2025'!N7 -> S9 | ... DF4: ='MODU 2025'!BF7 -> S52+1 | DH4: ='MODU 2025'!G7 -> S2 | DI4: ='MODU 2025'!H7 -> S3 | DJ4: ='MODU 2025'!I7 -> S4 | DK4: ='MODU 2025'!J7 -> S5 | DL4: ='MODU 2025'!K7 -> S6 | DM4: ='MODU 2025'!L7 -> S7 | DN4: ='MODU 2025'!M7 -> S8 | DO4: ='MODU 2025'!N7 -> S9 | ... FG4: ='MODU 2025'!BF7 -> S52+1 | FH4: Total | FJ4: ='MODU 2025'!G7 -> S2 | FK4: ='MODU 2025'!H7 -> S3 | FL4: ='MODU 2025'!I7 -> S4 | FM4: ='MODU 2025'!J7 -> S5 | FN4: ='MODU 2025'!K7 -> S6 | FO4: ='MODU 2025'!L7 -> S7 | FP4: ='MODU 2025'!M7 -> S8 | FQ4: ='MODU 2025'!N7 -> S9 | ... HI4: ='MODU 2025'!BF7 -> S52+1 | HJ4: Total | HL4: ='MODU 2025'!G7 -> S2 | HM4: ='MODU 2025'!H7 -> S3 | HN4: ='MODU 2025'!I7 -> S4 | HO4: ='MODU 2025'!J7 -> S5 | HP4: ='MODU 2025'!K7 -> S6 | HQ4: ='MODU 2025'!L7 -> S7 | HR4: ='MODU 2025'!M7 -> S8 | HS4: ='MODU 2025'!N7 -> S9 | ... JK4: ='MODU 2025'!BF7 -> S52+1 | JL4: Total | JO4: =FJ3 -> 1.25 | JP4: =HL3 -> 1.5 | JQ4: Total majoré | JS4: Heures recupérées | JU4: Déduction travail - prévu
B5: ='MODU 2025'!B8 -> ABDELADIM Adem | C5: ='MODU 2025'!C8 -> Production | D5: ='MODU 2025'!D8 -> 37 | F5: ='MODU 2025'!G8 -> 37 | G5: ='MODU 2025'!H8 -> 37 | H5: ='MODU 2025'!I8 -> 37 | I5: ='MODU 2025'!J8 -> 37 | J5: ='MODU 2025'!K8 -> 37 | K5: ='MODU 2025'!L8 -> 41 | L5: ='MODU 2025'!M8 -> 33 | M5: ='MODU 2025'!N8 -> 41 | ... BE5: ='MODU 2025'!BF8 -> 41 | BG5: 37 | BH5: 37 | BI5: 37 | BJ5: 37 | BK5: 37 | BL5: 33 | BM5: 41 | BN5: 33 | BO5: 41 | BP5: 33 | BQ5: 41 | BR5: 33 | BS5: 41 | BT5: 33 | BU5: 41 | BV5: 33 | BW5: 41 | BX5: 33 | BY5: 41 | BZ5: 33 | CA5: 41 | CB5: 33 | CC5: 41 | CD5: 33 | CE5: 41 | CF5: 33 | CG5: 41 | CH5: 33 | CI5: 41 | CJ5: 33 | CK5: 41 | CL5: 33 | CM5: 41 | CN5: 33 | CO5: 41 | CP5: 33 | CQ5: 41 | CR5: 33 | CS5: 41 | CT5: 33 | CU5: 41 | CV5: 33 | CW5: 41 | CX5: 33 | CY5: 41 | CZ5: 33 | DA5: 41 | DB5: 33 | DC5: 41 | DD5: 33 | DE5: 41 | DF5: 33 | DH5: =IF( $C5="Production", IF(MOD(COLUMN(),2)=$DH$3,SUM(E5:F5)-SUM(BF5:BG5),0), F5-BG5) -> 0 | DI5: =IF( $C5="Production", IF(MOD(COLUMN(),2)=$DH$3,SUM(F5:G5)-SUM(BG5:BH5),0), G5-BH5) -> 0 | DJ5: =IF( $C5="Production", IF(MOD(COLUMN(),2)=$DH$3,SUM(G5:H5)-SUM(BH5:BI5),0), H5-BI5) -> 0 | DK5: =IF( $C5="Production", IF(MOD(COLUMN(),2)=$DH$3,SUM(H5:I5)-SUM(BI5:BJ5),0), I5-BJ5) -> 0 | DL5: =IF( $C5="Production", IF(MOD(COLUMN(),2)=$DH$3,SUM(I5:J5)-SUM(BJ5:BK5),0), J5-BK5) -> 0 | DM5: =IF( $C5="Production", IF(MOD(COLUMN(),2)=$DH$3,SUM(J5:K5)-SUM(BK5:BL5),0), K5-BL5) -> 8 | DN5: =IF( $C5="Production", IF(MOD(COLUMN(),2)=$DH$3,SUM(K5:L5)-SUM(BL5:BM5),0), L5-BM5) -> 0 | DO5: =IF( $C5="Production", IF(MOD(COLUMN(),2)=$DH$3,SUM(L5:M5)-SUM(BM5:BN5),0), M5-BN5) -> 0 | ... FG5: =IF( $C5="Production", IF(MOD(COLUMN(),2)=$DH$3,SUM(BD5:BE5)-SUM(DE5:DF5),0), BE5-DF5) -> 0 | FH5: =SUM(DH5:FG5) -> 8 | FJ5: {=IF($C5="Production", IFERROR(_xlfn.IFS(AND(DH5>0,DH5+SUM(BF5:BG5)<=$FM$3),DH5,AND(DH5>0,DH5+SUM(BF5:BG5)>$FM$3),$FM$3-SUM(BF5:BG5)),0), IFERROR(_xlfn.IFS(AND(DH5>0,DH5+BG5<=$FK$3),DH5,AND(DH5>0,DH5+BG5>$FK$3),0),0) )} -> 0 | FK5: {=IF($C5="Production", IFERROR(_xlfn.IFS(AND(DI5>0,DI5+SUM(BG5:BH5)<=$FM$3),DI5,AND(DI5>0,DI5+SUM(BG5:BH5)>$FM$3),$FM$3-SUM(BG5:BH5)),0), IFERROR(_xlfn.IFS(AND(DI5>0,DI5+BH5<=$FK$3),DI5,AND(DI5>0,DI5+BH5>$FK$3),0),0) )} -> 0 | FL5: {=IF($C5="Production", IFERROR(_xlfn.IFS(AND(DJ5>0,DJ5+SUM(BH5:BI5)<=$FM$3),DJ5,AND(DJ5>0,DJ5+SUM(BH5:BI5)>$FM$3),$FM$3-SUM(BH5:BI5)),0), IFERROR(_xlfn.IFS(AND(DJ5>0,DJ5+BI5<=$FK$3),DJ5,AND(DJ5>0,DJ5+BI5>$FK$3),0),0) )} -> 0 | FM5: {=IF($C5="Production", IFERROR(_xlfn.IFS(AND(DK5>0,DK5+SUM(BI5:BJ5)<=$FM$3),DK5,AND(DK5>0,DK5+SUM(BI5:BJ5)>$FM$3),$FM$3-SUM(BI5:BJ5)),0), IFERROR(_xlfn.IFS(AND(DK5>0,DK5+BJ5<=$FK$3),DK5,AND(DK5>0,DK5+BJ5>$FK$3),0),0) )} -> 0 | FN5: {=IF($C5="Production", IFERROR(_xlfn.IFS(AND(DL5>0,DL5+SUM(BJ5:BK5)<=$FM$3),DL5,AND(DL5>0,DL5+SUM(BJ5:BK5)>$FM$3),$FM$3-SUM(BJ5:BK5)),0), IFERROR(_xlfn.IFS(AND(DL5>0,DL5+BK5<=$FK$3),DL5,AND(DL5>0,DL5+BK5>$FK$3),0),0) )} -> 0 | FO5: {=IF($C5="Production", IFERROR(_xlfn.IFS(AND(DM5>0,DM5+SUM(BK5:BL5)<=$FM$3),DM5,AND(DM5>0,DM5+SUM(BK5:BL5)>$FM$3),$FM$3-SUM(BK5:BL5)),0), IFERROR(_xlfn.IFS(AND(DM5>0,DM5+BL5<=$FK$3),DM5,AND(DM5>0,DM5+BL5>$FK$3),0),0) )} -> 8 | FP5: {=IF($C5="Production", IFERROR(_xlfn.IFS(AND(DN5>0,DN5+SUM(BL5:BM5)<=$FM$3),DN5,AND(DN5>0,DN5+SUM(BL5:BM5)>$FM$3),$FM$3-SUM(BL5:BM5)),0), IFERROR(_xlfn.IFS(AND(DN5>0,DN5+BM5<=$FK$3),DN5,AND(DN5>0,DN5+BM5>$FK$3),0),0) )} -> 0 | FQ5: {=IF($C5="Production", IFERROR(_xlfn.IFS(AND(DO5>0,DO5+SUM(BM5:BN5)<=$FM$3),DO5,AND(DO5>0,DO5+SUM(BM5:BN5)>$FM$3),$FM$3-SUM(BM5:BN5)),0), IFERROR(_xlfn.IFS(AND(DO5>0,DO5+BN5<=$FK$3),DO5,AND(DO5>0,DO5+BN5>$FK$3),0),0) )} -> 0 | ... HI5: {=IF($C5="Production", IFERROR(_xlfn.IFS(AND(FG5>0,FG5+SUM(DE5:DF5)<=$FM$3),FG5,AND(FG5>0,FG5+SUM(DE5:DF5)>$FM$3),$FM$3-SUM(DE5:DF5)),0), IFERROR(_xlfn.IFS(AND(FG5>0,FG5+DF5<=$FK$3),FG5,AND(FG5>0,FG5+DF5>$FK$3),0),0) )} -> 0 | HJ5: =SUM(FJ5:HI5) -> 8 | HL5: =IFERROR(IF(FJ5>0,DH5-FJ5,0),0) -> 0 | HM5: =IFERROR(IF(FK5>0,DI5-FK5,0),0) -> 0 | HN5: =IFERROR(IF(FL5>0,DJ5-FL5,0),0) -> 0 | HO5: =IFERROR(IF(FM5>0,DK5-FM5,0),0) -> 0 | HP5: =IFERROR(IF(FN5>0,DL5-FN5,0),0) -> 0 | HQ5: =IFERROR(IF(FO5>0,DM5-FO5,0),0) -> 0 | HR5: =IFERROR(IF(FP5>0,DN5-FP5,0),0) -> 0 | HS5: =IFERROR(IF(FQ5>0,DO5-FQ5,0),0) -> 0 | ... JK5: =IFERROR(IF(HI5>0,FG5-HI5,0),0) -> 0 | JL5: =SUM(HL5:JK5) -> 0 | JO5: =HJ5 -> 8 | JP5: =JL5 -> 0 | JQ5: =$JO$4*JO5+$JP$4*JP5 -> 10 | JS5: =SUMIFS(DH5:FG5,DH5:FG5,"<0") -> 0 | JU5: =JQ5+JS5 -> 10
B6: ='MODU 2025'!B9 -> ALVES Sylvie | C6: ='MODU 2025'!C9 -> Production CE | D6: ='MODU 2025'!D9 -> 39 | F6: ='MODU 2025'!G9 -> 41.5 | G6: ='MODU 2025'!H9 -> 40.5 | H6: ='MODU 2025'!I9 -> 39 | I6: ='MODU 2025'!J9 -> 42.5 | J6: ='MODU 2025'!K9 -> 39 | K6: ='MODU 2025'!L9 -> 40 | L6: ='MODU 2025'!M9 -> 39 | M6: ='MODU 2025'!N9 -> 39 | ... BE6: ='MODU 2025'!BF9 -> 39 | BG6: 39 | BH6: 39 | BI6: 39 | BJ6: 39 | BK6: 39 | BL6: 39 | BM6: 39 | BN6: 39 | BO6: 39 | BP6: 39 | BQ6: 39 | BR6: 39 | BS6: 39 | BT6: 39 | BU6: 39 | BV6: 39 | BW6: 39 | BX6: 39 | BY6: 39 | BZ6: 39 | CA6: 39 | CB6: 39 | CC6: 39 | CD6: 39 | CE6: 39 | CF6: 39 | CG6: 39 | CH6: 39 | CI6: 39 | CJ6: 39 | CK6: 39 | CL6: 39 | CM6: 39 | CN6: 39 | CO6: 39 | CP6: 39 | CQ6: 39 | CR6: 39 | CS6: 39 | CT6: 39 | CU6: 39 | CV6: 39 | CW6: 39 | CX6: 39 | CY6: 39 | CZ6: 39 | DA6: 39 | DB6: 39 | DC6: 39 | DD6: 39 | DE6: 39 | DF6: 39 | DH6: =IF( $C6="Production", IF(MOD(COLUMN(),2)=$DH$3,SUM(E6:F6)-SUM(BF6:BG6),0), F6-BG6) -> 2.5 | DI6: =IF( $C6="Production", IF(MOD(COLUMN(),2)=$DH$3,SUM(F6:G6)-SUM(BG6:BH6),0), G6-BH6) -> 1.5 | DJ6: =IF( $C6="Production", IF(MOD(COLUMN(),2)=$DH$3,SUM(G6:H6)-SUM(BH6:BI6),0), H6-BI6) -> 0 | DK6: =IF( $C6="Production", IF(MOD(COLUMN(),2)=$DH$3,SUM(H6:I6)-SUM(BI6:BJ6),0), I6-BJ6) -> 3.5 | DL6: =IF( $C6="Production", IF(MOD(COLUMN(),2)=$DH$3,SUM(I6:J6)-SUM(BJ6:BK6),0), J6-BK6) -> 0 | DM6: =IF( $C6="Production", IF(MOD(COLUMN(),2)=$DH$3,SUM(J6:K6)-SUM(BK6:BL6),0), K6-BL6) -> 1 | DN6: =IF( $C6="Production", IF(MOD(COLUMN(),2)=$DH$3,SUM(K6:L6)-SUM(BL6:BM6),0), L6-BM6) -> 0 | DO6: =IF( $C6="Production", IF(MOD(COLUMN(),2)=$DH$3,SUM(L6:M6)-SUM(BM6:BN6),0), M6-BN6) -> 0 | ... FG6: =IF( $C6="Production", IF(MOD(COLUMN(),2)=$DH$3,SUM(BD6:BE6)-SUM(DE6:DF6),0), BE6-DF6) -> 0 | FH6: =SUM(DH6:FG6) -> 12 | FJ6: {=IF($C6="Production", IFERROR(_xlfn.IFS(AND(DH6>0,DH6+SUM(BF6:BG6)<=$FM$3),DH6,AND(DH6>0,DH6+SUM(BF6:BG6)>$FM$3),$FM$3-SUM(BF6:BG6)),0), IFERROR(_xlfn.IFS(AND(DH6>0,DH6+BG6<=$FK$3),DH6,AND(DH6>0,DH6+BG6>$FK$3),0),0) )} -> 2.5 | FK6: {=IF($C6="Production", IFERROR(_xlfn.IFS(AND(DI6>0,DI6+SUM(BG6:BH6)<=$FM$3),DI6,AND(DI6>0,DI6+SUM(BG6:BH6)>$FM$3),$FM$3-SUM(BG6:BH6)),0), IFERROR(_xlfn.IFS(AND(DI6>0,DI6+BH6<=$FK$3),DI6,AND(DI6>0,DI6+BH6>$FK$3),0),0) )} -> 1.5 | FL6: {=IF($C6="Production", IFERROR(_xlfn.IFS(AND(DJ6>0,DJ6+SUM(BH6:BI6)<=$FM$3),DJ6,AND(DJ6>0,DJ6+SUM(BH6:BI6)>$FM$3),$FM$3-SUM(BH6:BI6)),0), IFERROR(_xlfn.IFS(AND(DJ6>0,DJ6+BI6<=$FK$3),DJ6,AND(DJ6>0,DJ6+BI6>$FK$3),0),0) )} -> 0 | FM6: {=IF($C6="Production", IFERROR(_xlfn.IFS(AND(DK6>0,DK6+SUM(BI6:BJ6)<=$FM$3),DK6,AND(DK6>0,DK6+SUM(BI6:BJ6)>$FM$3),$FM$3-SUM(BI6:BJ6)),0), IFERROR(_xlfn.IFS(AND(DK6>0,DK6+BJ6<=$FK$3),DK6,AND(DK6>0,DK6+BJ6>$FK$3),0),0) )} -> 3.5 | FN6: {=IF($C6="Production", IFERROR(_xlfn.IFS(AND(DL6>0,DL6+SUM(BJ6:BK6)<=$FM$3),DL6,AND(DL6>0,DL6+SUM(BJ6:BK6)>$FM$3),$FM$3-SUM(BJ6:BK6)),0), IFERROR(_xlfn.IFS(AND(DL6>0,DL6+BK6<=$FK$3),DL6,AND(DL6>0,DL6+BK6>$FK$3),0),0) )} -> 0 | FO6: {=IF($C6="Production", IFERROR(_xlfn.IFS(AND(DM6>0,DM6+SUM(BK6:BL6)<=$FM$3),DM6,AND(DM6>0,DM6+SUM(BK6:BL6)>$FM$3),$FM$3-SUM(BK6:BL6)),0), IFERROR(_xlfn.IFS(AND(DM6>0,DM6+BL6<=$FK$3),DM6,AND(DM6>0,DM6+BL6>$FK$3),0),0) )} -> 1 | FP6: {=IF($C6="Production", IFERROR(_xlfn.IFS(AND(DN6>0,DN6+SUM(BL6:BM6)<=$FM$3),DN6,AND(DN6>0,DN6+SUM(BL6:BM6)>$FM$3),$FM$3-SUM(BL6:BM6)),0), IFERROR(_xlfn.IFS(AND(DN6>0,DN6+BM6<=$FK$3),DN6,AND(DN6>0,DN6+BM6>$FK$3),0),0) )} -> 0 | FQ6: {=IF($C6="Production", IFERROR(_xlfn.IFS(AND(DO6>0,DO6+SUM(BM6:BN6)<=$FM$3),DO6,AND(DO6>0,DO6+SUM(BM6:BN6)>$FM$3),$FM$3-SUM(BM6:BN6)),0), IFERROR(_xlfn.IFS(AND(DO6>0,DO6+BN6<=$FK$3),DO6,AND(DO6>0,DO6+BN6>$FK$3),0),0) )} -> 0 | ... HI6: {=IF($C6="Production", IFERROR(_xlfn.IFS(AND(FG6>0,FG6+SUM(DE6:DF6)<=$FM$3),FG6,AND(FG6>0,FG6+SUM(DE6:DF6)>$FM$3),$FM$3-SUM(DE6:DF6)),0), IFERROR(_xlfn.IFS(AND(FG6>0,FG6+DF6<=$FK$3),FG6,AND(FG6>0,FG6+DF6>$FK$3),0),0) )} -> 0 | HJ6: =SUM(FJ6:HI6) -> 12 | HL6: =IFERROR(IF(FJ6>0,DH6-FJ6,0),0) -> 0 | HM6: =IFERROR(IF(FK6>0,DI6-FK6,0),0) -> 0 | HN6: =IFERROR(IF(FL6>0,DJ6-FL6,0),0) -> 0 | HO6: =IFERROR(IF(FM6>0,DK6-FM6,0),0) -> 0 | HP6: =IFERROR(IF(FN6>0,DL6-FN6,0),0) -> 0 | HQ6: =IFERROR(IF(FO6>0,DM6-FO6,0),0) -> 0 | HR6: =IFERROR(IF(FP6>0,DN6-FP6,0),0) -> 0 | HS6: =IFERROR(IF(FQ6>0,DO6-FQ6,0),0) -> 0 | ... JK6: =IFERROR(IF(HI6>0,FG6-HI6,0),0) -> 0 | JL6: =SUM(HL6:JK6) -> 0 | JO6: =HJ6 -> 12 | JP6: =JL6 -> 0 | JQ6: =$JO$4*JO6+$JP$4*JP6 -> 15 | JS6: =SUMIFS(DH6:FG6,DH6:FG6,"<0") -> 0 | JU6: =JQ6+JS6 -> 15
B7: ='MODU 2025'!B10 -> BALLOT Lucas | C7: ='MODU 2025'!C10 -> Production | D7: ='MODU 2025'!D10 -> 37 | F7: ='MODU 2025'!G10 -> 37 | G7: ='MODU 2025'!H10 -> 37 | H7: ='MODU 2025'!I10 -> 37 | I7: ='MODU 2025'!J10 -> 37 | J7: ='MODU 2025'!K10 -> 37 | K7: ='MODU 2025'!L10 -> 37 | L7: ='MODU 2025'!M10 -> 37 | M7: ='MODU 2025'!N10 -> 37 | ... BE7: ='MODU 2025'!BF10 -> 33 | BG7: 41 | BH7: 33 | BI7: 41 | BJ7: 33 | BK7: 41 | BL7: 33 | BM7: 41 | BN7: 33 | BO7: 41 | BP7: 33 | BQ7: 41 | BR7: 33 | BS7: 41 | BT7: 33 | BU7: 41 | BV7: 33 | BW7: 41 | BX7: 33 | BY7: 41 | BZ7: 33 | CA7: 41 | CB7: 33 | CC7: 41 | CD7: 33 | CE7: 41 | CF7: 33 | CG7: 41 | CH7: 33 | CI7: 41 | CJ7: 33 | CK7: 41 | CL7: 33 | CM7: 41 | CN7: 33 | CO7: 41 | CP7: 33 | CQ7: 41 | CR7: 33 | CS7: 41 | CT7: 33 | CU7: 41 | CV7: 33 | CW7: 41 | CX7: 33 | CY7: 41 | CZ7: 33 | DA7: 41 | DB7: 33 | DC7: 41 | DD7: 33 | DE7: 41 | DF7: 33 | DH7: =IF( $C7="Production", IF(MOD(COLUMN(),2)=$DH$3,SUM(E7:F7)-SUM(BF7:BG7),0), F7-BG7) -> 0 | DI7: =IF( $C7="Production", IF(MOD(COLUMN(),2)=$DH$3,SUM(F7:G7)-SUM(BG7:BH7),0), G7-BH7) -> 0 | DJ7: =IF( $C7="Production", IF(MOD(COLUMN(),2)=$DH$3,SUM(G7:H7)-SUM(BH7:BI7),0), H7-BI7) -> 0 | DK7: =IF( $C7="Production", IF(MOD(COLUMN(),2)=$DH$3,SUM(H7:I7)-SUM(BI7:BJ7),0), I7-BJ7) -> 0 | DL7: =IF( $C7="Production", IF(MOD(COLUMN(),2)=$DH$3,SUM(I7:J7)-SUM(BJ7:BK7),0), J7-BK7) -> 0 | DM7: =IF( $C7="Production", IF(MOD(COLUMN(),2)=$DH$3,SUM(J7:K7)-SUM(BK7:BL7),0), K7-BL7) -> 0 | DN7: =IF( $C7="Production", IF(MOD(COLUMN(),2)=$DH$3,SUM(K7:L7)-SUM(BL7:BM7),0), L7-BM7) -> 0 | DO7: =IF( $C7="Production", IF(MOD(COLUMN(),2)=$DH$3,SUM(L7:M7)-SUM(BM7:BN7),0), M7-BN7) -> 0 | ... FG7: =IF( $C7="Production", IF(MOD(COLUMN(),2)=$DH$3,SUM(BD7:BE7)-SUM(DE7:DF7),0), BE7-DF7) -> 0 | FH7: =SUM(DH7:FG7) -> 0 | FJ7: {=IF($C7="Production", IFERROR(_xlfn.IFS(AND(DH7>0,DH7+SUM(BF7:BG7)<=$FM$3),DH7,AND(DH7>0,DH7+SUM(BF7:BG7)>$FM$3),$FM$3-SUM(BF7:BG7)),0), IFERROR(_xlfn.IFS(AND(DH7>0,DH7+BG7<=$FK$3),DH7,AND(DH7>0,DH7+BG7>$FK$3),0),0) )} -> 0 | FK7: {=IF($C7="Production", IFERROR(_xlfn.IFS(AND(DI7>0,DI7+SUM(BG7:BH7)<=$FM$3),DI7,AND(DI7>0,DI7+SUM(BG7:BH7)>$FM$3),$FM$3-SUM(BG7:BH7)),0), IFERROR(_xlfn.IFS(AND(DI7>0,DI7+BH7<=$FK$3),DI7,AND(DI7>0,DI7+BH7>$FK$3),0),0) )} -> 0 | FL7: {=IF($C7="Production", IFERROR(_xlfn.IFS(AND(DJ7>0,DJ7+SUM(BH7:BI7)<=$FM$3),DJ7,AND(DJ7>0,DJ7+SUM(BH7:BI7)>$FM$3),$FM$3-SUM(BH7:BI7)),0), IFERROR(_xlfn.IFS(AND(DJ7>0,DJ7+BI7<=$FK$3),DJ7,AND(DJ7>0,DJ7+BI7>$FK$3),0),0) )} -> 0 | FM7: {=IF($C7="Production", IFERROR(_xlfn.IFS(AND(DK7>0,DK7+SUM(BI7:BJ7)<=$FM$3),DK7,AND(DK7>0,DK7+SUM(BI7:BJ7)>$FM$3),$FM$3-SUM(BI7:BJ7)),0), IFERROR(_xlfn.IFS(AND(DK7>0,DK7+BJ7<=$FK$3),DK7,AND(DK7>0,DK7+BJ7>$FK$3),0),0) )} -> 0 | FN7: {=IF($C7="Production", IFERROR(_xlfn.IFS(AND(DL7>0,DL7+SUM(BJ7:BK7)<=$FM$3),DL7,AND(DL7>0,DL7+SUM(BJ7:BK7)>$FM$3),$FM$3-SUM(BJ7:BK7)),0), IFERROR(_xlfn.IFS(AND(DL7>0,DL7+BK7<=$FK$3),DL7,AND(DL7>0,DL7+BK7>$FK$3),0),0) )} -> 0 | FO7: {=IF($C7="Production", IFERROR(_xlfn.IFS(AND(DM7>0,DM7+SUM(BK7:BL7)<=$FM$3),DM7,AND(DM7>0,DM7+SUM(BK7:BL7)>$FM$3),$FM$3-SUM(BK7:BL7)),0), IFERROR(_xlfn.IFS(AND(DM7>0,DM7+BL7<=$FK$3),DM7,AND(DM7>0,DM7+BL7>$FK$3),0),0) )} -> 0 | FP7: {=IF($C7="Production", IFERROR(_xlfn.IFS(AND(DN7>0,DN7+SUM(BL7:BM7)<=$FM$3),DN7,AND(DN7>0,DN7+SUM(BL7:BM7)>$FM$3),$FM$3-SUM(BL7:BM7)),0), IFERROR(_xlfn.IFS(AND(DN7>0,DN7+BM7<=$FK$3),DN7,AND(DN7>0,DN7+BM7>$FK$3),0),0) )} -> 0 | FQ7: {=IF($C7="Production", IFERROR(_xlfn.IFS(AND(DO7>0,DO7+SUM(BM7:BN7)<=$FM$3),DO7,AND(DO7>0,DO7+SUM(BM7:BN7)>$FM$3),$FM$3-SUM(BM7:BN7)),0), IFERROR(_xlfn.IFS(AND(DO7>0,DO7+BN7<=$FK$3),DO7,AND(DO7>0,DO7+BN7>$FK$3),0),0) )} -> 0 | ... HI7: {=IF($C7="Production", IFERROR(_xlfn.IFS(AND(FG7>0,FG7+SUM(DE7:DF7)<=$FM$3),FG7,AND(FG7>0,FG7+SUM(DE7:DF7)>$FM$3),$FM$3-SUM(DE7:DF7)),0), IFERROR(_xlfn.IFS(AND(FG7>0,FG7+DF7<=$FK$3),FG7,AND(FG7>0,FG7+DF7>$FK$3),0),0) )} -> 0 | HJ7: =SUM(FJ7:HI7) -> 0 | HL7: =IFERROR(IF(FJ7>0,DH7-FJ7,0),0) -> 0 | HM7: =IFERROR(IF(FK7>0,DI7-FK7,0),0) -> 0 | HN7: =IFERROR(IF(FL7>0,DJ7-FL7,0),0) -> 0 | HO7: =IFERROR(IF(FM7>0,DK7-FM7,0),0) -> 0 | HP7: =IFERROR(IF(FN7>0,DL7-FN7,0),0) -> 0 | HQ7: =IFERROR(IF(FO7>0,DM7-FO7,0),0) -> 0 | HR7: =IFERROR(IF(FP7>0,DN7-FP7,0),0) -> 0 | HS7: =IFERROR(IF(FQ7>0,DO7-FQ7,0),0) -> 0 | ... JK7: =IFERROR(IF(HI7>0,FG7-HI7,0),0) -> 0 | JL7: =SUM(HL7:JK7) -> 0 | JO7: =HJ7 -> 0 | JP7: =JL7 -> 0 | JQ7: =$JO$4*JO7+$JP$4*JP7 -> 0 | JS7: =SUMIFS(DH7:FG7,DH7:FG7,"<0") -> 0 | JU7: =JQ7+JS7 -> 0
B8: ='MODU 2025'!B11 -> BOLLET DURAFOUR Bérangère | C8: ='MODU 2025'!C11 -> Production | D8: ='MODU 2025'!D11 -> 37 | F8: ='MODU 2025'!G11 -> 41 | G8: ='MODU 2025'!H11 -> 33 | H8: ='MODU 2025'!I11 -> 41 | I8: ='MODU 2025'!J11 -> 33 | J8: ='MODU 2025'!K11 -> 41 | K8: ='MODU 2025'!L11 -> 33 | L8: ='MODU 2025'!M11 -> 41 | M8: ='MODU 2025'!N11 -> 33 | ... BE8: ='MODU 2025'!BF11 -> 33 | BG8: 41 | BH8: 33 | BI8: 41 | BJ8: 33 | BK8: 41 | BL8: 33 | BM8: 41 | BN8: 33 | BO8: 41 | BP8: 33 | BQ8: 41 | BR8: 33 | BS8: 41 | BT8: 33 | BU8: 41 | BV8: 33 | BW8: 41 | BX8: 33 | BY8: 41 | BZ8: 33 | CA8: 41 | CB8: 33 | CC8: 41 | CD8: 33 | CE8: 41 | CF8: 33 | CG8: 41 | CH8: 33 | CI8: 41 | CJ8: 33 | CK8: 41 | CL8: 33 | CM8: 41 | CN8: 33 | CO8: 41 | CP8: 33 | CQ8: 41 | CR8: 33 | CS8: 41 | CT8: 33 | CU8: 41 | CV8: 33 | CW8: 41 | CX8: 33 | CY8: 41 | CZ8: 33 | DA8: 41 | DB8: 33 | DC8: 41 | DD8: 33 | DE8: 41 | DF8: 33 | DH8: =IF( $C8="Production", IF(MOD(COLUMN(),2)=$DH$3,SUM(E8:F8)-SUM(BF8:BG8),0), F8-BG8) -> 0 | DI8: =IF( $C8="Production", IF(MOD(COLUMN(),2)=$DH$3,SUM(F8:G8)-SUM(BG8:BH8),0), G8-BH8) -> 0 | DJ8: =IF( $C8="Production", IF(MOD(COLUMN(),2)=$DH$3,SUM(G8:H8)-SUM(BH8:BI8),0), H8-BI8) -> 0 | DK8: =IF( $C8="Production", IF(MOD(COLUMN(),2)=$DH$3,SUM(H8:I8)-SUM(BI8:BJ8),0), I8-BJ8) -> 0 | DL8: =IF( $C8="Production", IF(MOD(COLUMN(),2)=$DH$3,SUM(I8:J8)-SUM(BJ8:BK8),0), J8-BK8) -> 0 | DM8: =IF( $C8="Production", IF(MOD(COLUMN(),2)=$DH$3,SUM(J8:K8)-SUM(BK8:BL8),0), K8-BL8) -> 0 | DN8: =IF( $C8="Production", IF(MOD(COLUMN(),2)=$DH$3,SUM(K8:L8)-SUM(BL8:BM8),0), L8-BM8) -> 0 | DO8: =IF( $C8="Production", IF(MOD(COLUMN(),2)=$DH$3,SUM(L8:M8)-SUM(BM8:BN8),0), M8-BN8) -> 0 | ... FG8: =IF( $C8="Production", IF(MOD(COLUMN(),2)=$DH$3,SUM(BD8:BE8)-SUM(DE8:DF8),0), BE8-DF8) -> 0 | FH8: =SUM(DH8:FG8) -> 0 | FJ8: {=IF($C8="Production", IFERROR(_xlfn.IFS(AND(DH8>0,DH8+SUM(BF8:BG8)<=$FM$3),DH8,AND(DH8>0,DH8+SUM(BF8:BG8)>$FM$3),$FM$3-SUM(BF8:BG8)),0), IFERROR(_xlfn.IFS(AND(DH8>0,DH8+BG8<=$FK$3),DH8,AND(DH8>0,DH8+BG8>$FK$3),0),0) )} -> 0 | FK8: {=IF($C8="Production", IFERROR(_xlfn.IFS(AND(DI8>0,DI8+SUM(BG8:BH8)<=$FM$3),DI8,AND(DI8>0,DI8+SUM(BG8:BH8)>$FM$3),$FM$3-SUM(BG8:BH8)),0), IFERROR(_xlfn.IFS(AND(DI8>0,DI8+BH8<=$FK$3),DI8,AND(DI8>0,DI8+BH8>$FK$3),0),0) )} -> 0 | FL8: {=IF($C8="Production", IFERROR(_xlfn.IFS(AND(DJ8>0,DJ8+SUM(BH8:BI8)<=$FM$3),DJ8,AND(DJ8>0,DJ8+SUM(BH8:BI8)>$FM$3),$FM$3-SUM(BH8:BI8)),0), IFERROR(_xlfn.IFS(AND(DJ8>0,DJ8+BI8<=$FK$3),DJ8,AND(DJ8>0,DJ8+BI8>$FK$3),0),0) )} -> 0 | FM8: {=IF($C8="Production", IFERROR(_xlfn.IFS(AND(DK8>0,DK8+SUM(BI8:BJ8)<=$FM$3),DK8,AND(DK8>0,DK8+SUM(BI8:BJ8)>$FM$3),$FM$3-SUM(BI8:BJ8)),0), IFERROR(_xlfn.IFS(AND(DK8>0,DK8+BJ8<=$FK$3),DK8,AND(DK8>0,DK8+BJ8>$FK$3),0),0) )} -> 0 | FN8: {=IF($C8="Production", IFERROR(_xlfn.IFS(AND(DL8>0,DL8+SUM(BJ8:BK8)<=$FM$3),DL8,AND(DL8>0,DL8+SUM(BJ8:BK8)>$FM$3),$FM$3-SUM(BJ8:BK8)),0), IFERROR(_xlfn.IFS(AND(DL8>0,DL8+BK8<=$FK$3),DL8,AND(DL8>0,DL8+BK8>$FK$3),0),0) )} -> 0 | FO8: {=IF($C8="Production", IFERROR(_xlfn.IFS(AND(DM8>0,DM8+SUM(BK8:BL8)<=$FM$3),DM8,AND(DM8>0,DM8+SUM(BK8:BL8)>$FM$3),$FM$3-SUM(BK8:BL8)),0), IFERROR(_xlfn.IFS(AND(DM8>0,DM8+BL8<=$FK$3),DM8,AND(DM8>0,DM8+BL8>$FK$3),0),0) )} -> 0 | FP8: {=IF($C8="Production", IFERROR(_xlfn.IFS(AND(DN8>0,DN8+SUM(BL8:BM8)<=$FM$3),DN8,AND(DN8>0,DN8+SUM(BL8:BM8)>$FM$3),$FM$3-SUM(BL8:BM8)),0), IFERROR(_xlfn.IFS(AND(DN8>0,DN8+BM8<=$FK$3),DN8,AND(DN8>0,DN8+BM8>$FK$3),0),0) )} -> 0 | FQ8: {=IF($C8="Production", IFERROR(_xlfn.IFS(AND(DO8>0,DO8+SUM(BM8:BN8)<=$FM$3),DO8,AND(DO8>0,DO8+SUM(BM8:BN8)>$FM$3),$FM$3-SUM(BM8:BN8)),0), IFERROR(_xlfn.IFS(AND(DO8>0,DO8+BN8<=$FK$3),DO8,AND(DO8>0,DO8+BN8>$FK$3),0),0) )} -> 0 | ... HI8: {=IF($C8="Production", IFERROR(_xlfn.IFS(AND(FG8>0,FG8+SUM(DE8:DF8)<=$FM$3),FG8,AND(FG8>0,FG8+SUM(DE8:DF8)>$FM$3),$FM$3-SUM(DE8:DF8)),0), IFERROR(_xlfn.IFS(AND(FG8>0,FG8+DF8<=$FK$3),FG8,AND(FG8>0,FG8+DF8>$FK$3),0),0) )} -> 0 | HJ8: =SUM(FJ8:HI8) -> 0 | HL8: =IFERROR(IF(FJ8>0,DH8-FJ8,0),0) -> 0 | HM8: =IFERROR(IF(FK8>0,DI8-FK8,0),0) -> 0 | HN8: =IFERROR(IF(FL8>0,DJ8-FL8,0),0) -> 0 | HO8: =IFERROR(IF(FM8>0,DK8-FM8,0),0) -> 0 | HP8: =IFERROR(IF(FN8>0,DL8-FN8,0),0) -> 0 | HQ8: =IFERROR(IF(FO8>0,DM8-FO8,0),0) -> 0 | HR8: =IFERROR(IF(FP8>0,DN8-FP8,0),0) -> 0 | HS8: =IFERROR(IF(FQ8>0,DO8-FQ8,0),0) -> 0 | ... JK8: =IFERROR(IF(HI8>0,FG8-HI8,0),0) -> 0 | JL8: =SUM(HL8:JK8) -> 0 | JO8: =HJ8 -> 0 | JP8: =JL8 -> 0 | JQ8: =$JO$4*JO8+$JP$4*JP8 -> 0 | JS8: =SUMIFS(DH8:FG8,DH8:FG8,"<0") -> 0 | JU8: =JQ8+JS8 -> 0
B9: ='MODU 2025'!B12 -> BONNERUE Sandrine | C9: ='MODU 2025'!C12 -> Production | D9: ='MODU 2025'!D12 -> 37 | F9: ='MODU 2025'!G12 -> 33 | G9: ='MODU 2025'!H12 -> 41 | H9: ='MODU 2025'!I12 -> 33 | I9: ='MODU 2025'!J12 -> 41 | J9: ='MODU 2025'!K12 -> 33 | K9: ='MODU 2025'!L12 -> 41 | L9: ='MODU 2025'!M12 -> 33 | M9: ='MODU 2025'!N12 -> 40.25 | ... BE9: ='MODU 2025'!BF12 -> 41 | BG9: 33 | BH9: 41 | BI9: 33 | BJ9: 41 | BK9: 33 | BL9: 41 | BM9: 33 | BN9: 41 | BO9: 33 | BP9: 41 | BQ9: 33 | BR9: 41 | BS9: 33 | BT9: 41 | BU9: 33 | BV9: 41 | BW9: 33 | BX9: 41 | BY9: 33 | BZ9: 41 | CA9: 33 | CB9: 41 | CC9: 33 | CD9: 41 | CE9: 33 | CF9: 41 | CG9: 33 | CH9: 41 | CI9: 33 | CJ9: 41 | CK9: 33 | CL9: 41 | CM9: 33 | CN9: 41 | CO9: 33 | CP9: 41 | CQ9: 33 | CR9: 41 | CS9: 33 | CT9: 41 | CU9: 33 | CV9: 41 | CW9: 33 | CX9: 41 | CY9: 33 | CZ9: 41 | DA9: 33 | DB9: 41 | DC9: 33 | DD9: 41 | DE9: 33 | DF9: 41 | DH9: =IF( $C9="Production", IF(MOD(COLUMN(),2)=$DH$3,SUM(E9:F9)-SUM(BF9:BG9),0), F9-BG9) -> 0 | DI9: =IF( $C9="Production", IF(MOD(COLUMN(),2)=$DH$3,SUM(F9:G9)-SUM(BG9:BH9),0), G9-BH9) -> 0 | DJ9: =IF( $C9="Production", IF(MOD(COLUMN(),2)=$DH$3,SUM(G9:H9)-SUM(BH9:BI9),0), H9-BI9) -> 0 | DK9: =IF( $C9="Production", IF(MOD(COLUMN(),2)=$DH$3,SUM(H9:I9)-SUM(BI9:BJ9),0), I9-BJ9) -> 0 | DL9: =IF( $C9="Production", IF(MOD(COLUMN(),2)=$DH$3,SUM(I9:J9)-SUM(BJ9:BK9),0), J9-BK9) -> 0 | DM9: =IF( $C9="Production", IF(MOD(COLUMN(),2)=$DH$3,SUM(J9:K9)-SUM(BK9:BL9),0), K9-BL9) -> 0 | DN9: =IF( $C9="Production", IF(MOD(COLUMN(),2)=$DH$3,SUM(K9:L9)-SUM(BL9:BM9),0), L9-BM9) -> 0 | DO9: =IF( $C9="Production", IF(MOD(COLUMN(),2)=$DH$3,SUM(L9:M9)-SUM(BM9:BN9),0), M9-BN9) -> -0.75 | ... FG9: =IF( $C9="Production", IF(MOD(COLUMN(),2)=$DH$3,SUM(BD9:BE9)-SUM(DE9:DF9),0), BE9-DF9) -> 0 | FH9: =SUM(DH9:FG9) -> 7.25 | FJ9: {=IF($C9="Production", IFERROR(_xlfn.IFS(AND(DH9>0,DH9+SUM(BF9:BG9)<=$FM$3),DH9,AND(DH9>0,DH9+SUM(BF9:BG9)>$FM$3),$FM$3-SUM(BF9:BG9)),0), IFERROR(_xlfn.IFS(AND(DH9>0,DH9+BG9<=$FK$3),DH9,AND(DH9>0,DH9+BG9>$FK$3),0),0) )} -> 0 | FK9: {=IF($C9="Production", IFERROR(_xlfn.IFS(AND(DI9>0,DI9+SUM(BG9:BH9)<=$FM$3),DI9,AND(DI9>0,DI9+SUM(BG9:BH9)>$FM$3),$FM$3-SUM(BG9:BH9)),0), IFERROR(_xlfn.IFS(AND(DI9>0,DI9+BH9<=$FK$3),DI9,AND(DI9>0,DI9+BH9>$FK$3),0),0) )} -> 0 | FL9: {=IF($C9="Production", IFERROR(_xlfn.IFS(AND(DJ9>0,DJ9+SUM(BH9:BI9)<=$FM$3),DJ9,AND(DJ9>0,DJ9+SUM(BH9:BI9)>$FM$3),$FM$3-SUM(BH9:BI9)),0), IFERROR(_xlfn.IFS(AND(DJ9>0,DJ9+BI9<=$FK$3),DJ9,AND(DJ9>0,DJ9+BI9>$FK$3),0),0) )} -> 0 | FM9: {=IF($C9="Production", IFERROR(_xlfn.IFS(AND(DK9>0,DK9+SUM(BI9:BJ9)<=$FM$3),DK9,AND(DK9>0,DK9+SUM(BI9:BJ9)>$FM$3),$FM$3-SUM(BI9:BJ9)),0), IFERROR(_xlfn.IFS(AND(DK9>0,DK9+BJ9<=$FK$3),DK9,AND(DK9>0,DK9+BJ9>$FK$3),0),0) )} -> 0 | FN9: {=IF($C9="Production", IFERROR(_xlfn.IFS(AND(DL9>0,DL9+SUM(BJ9:BK9)<=$FM$3),DL9,AND(DL9>0,DL9+SUM(BJ9:BK9)>$FM$3),$FM$3-SUM(BJ9:BK9)),0), IFERROR(_xlfn.IFS(AND(DL9>0,DL9+BK9<=$FK$3),DL9,AND(DL9>0,DL9+BK9>$FK$3),0),0) )} -> 0 | FO9: {=IF($C9="Production", IFERROR(_xlfn.IFS(AND(DM9>0,DM9+SUM(BK9:BL9)<=$FM$3),DM9,AND(DM9>0,DM9+SUM(BK9:BL9)>$FM$3),$FM$3-SUM(BK9:BL9)),0), IFERROR(_xlfn.IFS(AND(DM9>0,DM9+BL9<=$FK$3),DM9,AND(DM9>0,DM9+BL9>$FK$3),0),0) )} -> 0 | FP9: {=IF($C9="Production", IFERROR(_xlfn.IFS(AND(DN9>0,DN9+SUM(BL9:BM9)<=$FM$3),DN9,AND(DN9>0,DN9+SUM(BL9:BM9)>$FM$3),$FM$3-SUM(BL9:BM9)),0), IFERROR(_xlfn.IFS(AND(DN9>0,DN9+BM9<=$FK$3),DN9,AND(DN9>0,DN9+BM9>$FK$3),0),0) )} -> 0 | FQ9: {=IF($C9="Production", IFERROR(_xlfn.IFS(AND(DO9>0,DO9+SUM(BM9:BN9)<=$FM$3),DO9,AND(DO9>0,DO9+SUM(BM9:BN9)>$FM$3),$FM$3-SUM(BM9:BN9)),0), IFERROR(_xlfn.IFS(AND(DO9>0,DO9+BN9<=$FK$3),DO9,AND(DO9>0,DO9+BN9>$FK$3),0),0) )} -> 0 | ... HI9: {=IF($C9="Production", IFERROR(_xlfn.IFS(AND(FG9>0,FG9+SUM(DE9:DF9)<=$FM$3),FG9,AND(FG9>0,FG9+SUM(DE9:DF9)>$FM$3),$FM$3-SUM(DE9:DF9)),0), IFERROR(_xlfn.IFS(AND(FG9>0,FG9+DF9<=$FK$3),FG9,AND(FG9>0,FG9+DF9>$FK$3),0),0) )} -> 0 | HJ9: =SUM(FJ9:HI9) -> 8 | HL9: =IFERROR(IF(FJ9>0,DH9-FJ9,0),0) -> 0 | HM9: =IFERROR(IF(FK9>0,DI9-FK9,0),0) -> 0 | HN9: =IFERROR(IF(FL9>0,DJ9-FL9,0),0) -> 0 | HO9: =IFERROR(IF(FM9>0,DK9-FM9,0),0) -> 0 | HP9: =IFERROR(IF(FN9>0,DL9-FN9,0),0) -> 0 | HQ9: =IFERROR(IF(FO9>0,DM9-FO9,0),0) -> 0 | HR9: =IFERROR(IF(FP9>0,DN9-FP9,0),0) -> 0 | HS9: =IFERROR(IF(FQ9>0,DO9-FQ9,0),0) -> 0 | ... JK9: =IFERROR(IF(HI9>0,FG9-HI9,0),0) -> 0 | JL9: =SUM(HL9:JK9) -> 0 | JO9: =HJ9 -> 8 | JP9: =JL9 -> 0 | JQ9: =$JO$4*JO9+$JP$4*JP9 -> 10 | JS9: =SUMIFS(DH9:FG9,DH9:FG9,"<0") -> -0.75 | JU9: =JQ9+JS9 -> 9.25
B10: ='MODU 2025'!B13 -> BOUDIER Laure | C10: ='MODU 2025'!C13 -> Production | D10: ='MODU 2025'!D13 -> 37 | F10: ='MODU 2025'!G13 -> 41 | G10: ='MODU 2025'!H13 -> 33 | H10: ='MODU 2025'!I13 -> 41 | I10: ='MODU 2025'!J13 -> 33 | J10: ='MODU 2025'!K13 -> 41 | K10: ='MODU 2025'!L13 -> 40.75 | L10: ='MODU 2025'!M13 -> 41.25 | M10: ='MODU 2025'!N13 -> 33 | ... BE10: ='MODU 2025'!BF13 -> 33 | BG10: 41 | BH10: 33 | BI10: 41 | BJ10: 33 | BK10: 41 | BL10: 33 | BM10: 41 | BN10: 33 | BO10: 41 | BP10: 33 | BQ10: 41 | BR10: 33 | BS10: 41 | BT10: 33 | BU10: 41 | BV10: 33 | BW10: 41 | BX10: 33 | BY10: 41 | BZ10: 33 | CA10: 41 | CB10: 33 | CC10: 41 | CD10: 33 | CE10: 41 | CF10: 33 | CG10: 41 | CH10: 33 | CI10: 41 | CJ10: 33 | CK10: 41 | CL10: 33 | CM10: 41 | CN10: 33 | CO10: 41 | CP10: 33 | CQ10: 41 | CR10: 33 | CS10: 41 | CT10: 33 | CU10: 41 | CV10: 33 | CW10: 41 | CX10: 33 | CY10: 41 | CZ10: 33 | DA10: 41 | DB10: 33 | DC10: 41 | DD10: 33 | DE10: 41 | DF10: 33 | DH10: =IF( $C10="Production", IF(MOD(COLUMN(),2)=$DH$3,SUM(E10:F10)-SUM(BF10:BG10),0), F10-BG10) -> 0 | DI10: =IF( $C10="Production", IF(MOD(COLUMN(),2)=$DH$3,SUM(F10:G10)-SUM(BG10:BH10),0), G10-BH10) -> 0 | DJ10: =IF( $C10="Production", IF(MOD(COLUMN(),2)=$DH$3,SUM(G10:H10)-SUM(BH10:BI10),0), H10-BI10) -> 0 | DK10: =IF( $C10="Production", IF(MOD(COLUMN(),2)=$DH$3,SUM(H10:I10)-SUM(BI10:BJ10),0), I10-BJ10) -> 0 | DL10: =IF( $C10="Production", IF(MOD(COLUMN(),2)=$DH$3,SUM(I10:J10)-SUM(BJ10:BK10),0), J10-BK10) -> 0 | DM10: =IF( $C10="Production", IF(MOD(COLUMN(),2)=$DH$3,SUM(J10:K10)-SUM(BK10:BL10),0), K10-BL10) -> 7.75 | DN10: =IF( $C10="Production", IF(MOD(COLUMN(),2)=$DH$3,SUM(K10:L10)-SUM(BL10:BM10),0), L10-BM10) -> 0 | DO10: =IF( $C10="Production", IF(MOD(COLUMN(),2)=$DH$3,SUM(L10:M10)-SUM(BM10:BN10),0), M10-BN10) -> 0.25 | ... FG10: =IF( $C10="Production", IF(MOD(COLUMN(),2)=$DH$3,SUM(BD10:BE10)-SUM(DE10:DF10),0), BE10-DF10) -> 0 | FH10: =SUM(DH10:FG10) -> 8 | FJ10: {=IF($C10="Production", IFERROR(_xlfn.IFS(AND(DH10>0,DH10+SUM(BF10:BG10)<=$FM$3),DH10,AND(DH10>0,DH10+SUM(BF10:BG10)>$FM$3),$FM$3-SUM(BF10:BG10)),0), IFERROR(_xlfn.IFS(AND(DH10>0,DH10+BG10<=$FK$3),DH10,AND(DH10>0,DH10+BG10>$FK$3),0),0) )} -> 0 | FK10: {=IF($C10="Production", IFERROR(_xlfn.IFS(AND(DI10>0,DI10+SUM(BG10:BH10)<=$FM$3),DI10,AND(DI10>0,DI10+SUM(BG10:BH10)>$FM$3),$FM$3-SUM(BG10:BH10)),0), IFERROR(_xlfn.IFS(AND(DI10>0,DI10+BH10<=$FK$3),DI10,AND(DI10>0,DI10+BH10>$FK$3),0),0) )} -> 0 | FL10: {=IF($C10="Production", IFERROR(_xlfn.IFS(AND(DJ10>0,DJ10+SUM(BH10:BI10)<=$FM$3),DJ10,AND(DJ10>0,DJ10+SUM(BH10:BI10)>$FM$3),$FM$3-SUM(BH10:BI10)),0), IFERROR(_xlfn.IFS(AND(DJ10>0,DJ10+BI10<=$FK$3),DJ10,AND(DJ10>0,DJ10+BI10>$FK$3),0),0) )} -> 0 | FM10: {=IF($C10="Production", IFERROR(_xlfn.IFS(AND(DK10>0,DK10+SUM(BI10:BJ10)<=$FM$3),DK10,AND(DK10>0,DK10+SUM(BI10:BJ10)>$FM$3),$FM$3-SUM(BI10:BJ10)),0), IFERROR(_xlfn.IFS(AND(DK10>0,DK10+BJ10<=$FK$3),DK10,AND(DK10>0,DK10+BJ10>$FK$3),0),0) )} -> 0 | FN10: {=IF($C10="Production", IFERROR(_xlfn.IFS(AND(DL10>0,DL10+SUM(BJ10:BK10)<=$FM$3),DL10,AND(DL10>0,DL10+SUM(BJ10:BK10)>$FM$3),$FM$3-SUM(BJ10:BK10)),0), IFERROR(_xlfn.IFS(AND(DL10>0,DL10+BK10<=$FK$3),DL10,AND(DL10>0,DL10+BK10>$FK$3),0),0) )} -> 0 | FO10: {=IF($C10="Production", IFERROR(_xlfn.IFS(AND(DM10>0,DM10+SUM(BK10:BL10)<=$FM$3),DM10,AND(DM10>0,DM10+SUM(BK10:BL10)>$FM$3),$FM$3-SUM(BK10:BL10)),0), IFERROR(_xlfn.IFS(AND(DM10>0,DM10+BL10<=$FK$3),DM10,AND(DM10>0,DM10+BL10>$FK$3),0),0) )} -> 7.75 | FP10: {=IF($C10="Production", IFERROR(_xlfn.IFS(AND(DN10>0,DN10+SUM(BL10:BM10)<=$FM$3),DN10,AND(DN10>0,DN10+SUM(BL10:BM10)>$FM$3),$FM$3-SUM(BL10:BM10)),0), IFERROR(_xlfn.IFS(AND(DN10>0,DN10+BM10<=$FK$3),DN10,AND(DN10>0,DN10+BM10>$FK$3),0),0) )} -> 0 | FQ10: {=IF($C10="Production", IFERROR(_xlfn.IFS(AND(DO10>0,DO10+SUM(BM10:BN10)<=$FM$3),DO10,AND(DO10>0,DO10+SUM(BM10:BN10)>$FM$3),$FM$3-SUM(BM10:BN10)),0), IFERROR(_xlfn.IFS(AND(DO10>0,DO10+BN10<=$FK$3),DO10,AND(DO10>0,DO10+BN10>$FK$3),0),0) )} -> 0.25 | ... HI10: {=IF($C10="Production", IFERROR(_xlfn.IFS(AND(FG10>0,FG10+SUM(DE10:DF10)<=$FM$3),FG10,AND(FG10>0,FG10+SUM(DE10:DF10)>$FM$3),$FM$3-SUM(DE10:DF10)),0), IFERROR(_xlfn.IFS(AND(FG10>0,FG10+DF10<=$FK$3),FG10,AND(FG10>0,FG10+DF10>$FK$3),0),0) )} -> 0 | HJ10: =SUM(FJ10:HI10) -> 8 | HL10: =IFERROR(IF(FJ10>0,DH10-FJ10,0),0) -> 0 | HM10: =IFERROR(IF(FK10>0,DI10-FK10,0),0) -> 0 | HN10: =IFERROR(IF(FL10>0,DJ10-FL10,0),0) -> 0 | HO10: =IFERROR(IF(FM10>0,DK10-FM10,0),0) -> 0 | HP10: =IFERROR(IF(FN10>0,DL10-FN10,0),0) -> 0 | HQ10: =IFERROR(IF(FO10>0,DM10-FO10,0),0) -> 0 | HR10: =IFERROR(IF(FP10>0,DN10-FP10,0),0) -> 0 | HS10: =IFERROR(IF(FQ10>0,DO10-FQ10,0),0) -> 0 | ... JK10: =IFERROR(IF(HI10>0,FG10-HI10,0),0) -> 0 | JL10: =SUM(HL10:JK10) -> 0 | JO10: =HJ10 -> 8 | JP10: =JL10 -> 0 | JQ10: =$JO$4*JO10+$JP$4*JP10 -> 10 | JS10: =SUMIFS(DH10:FG10,DH10:FG10,"<0") -> 0 | JU10: =JQ10+JS10 -> 10
B11: ='MODU 2025'!B14 -> BOUILLET Dominique | C11: ='MODU 2025'!C14 -> Production | D11: ='MODU 2025'!D14 -> 37 | F11: ='MODU 2025'!G14 -> 33 | G11: ='MODU 2025'!H14 -> 36.75 | H11: ='MODU 2025'!I14 -> 33 | I11: ='MODU 2025'!J14 -> 41.25 | J11: ='MODU 2025'!K14 -> 40.75 | K11: ='MODU 2025'!L14 -> 41.5 | L11: ='MODU 2025'!M14 -> 40.75 | M11: ='MODU 2025'!N14 -> 41.75 | ... BE11: ='MODU 2025'!BF14 -> 41 | BG11: 33 | BH11: 41 | BI11: 33 | BJ11: 41 | BK11: 33 | BL11: 41 | BM11: 33 | BN11: 41 | BO11: 33 | BP11: 41 | BQ11: 33 | BR11: 41 | BS11: 33 | BT11: 41 | BU11: 33 | BV11: 41 | BW11: 33 | BX11: 41 | BY11: 33 | BZ11: 41 | CA11: 33 | CB11: 41 | CC11: 33 | CD11: 41 | CE11: 33 | CF11: 41 | CG11: 33 | CH11: 41 | CI11: 33 | CJ11: 41 | CK11: 33 | CL11: 41 | CM11: 33 | CN11: 41 | CO11: 33 | CP11: 41 | CQ11: 33 | CR11: 41 | CS11: 33 | CT11: 41 | CU11: 33 | CV11: 41 | CW11: 33 | CX11: 41 | CY11: 33 | CZ11: 41 | DA11: 33 | DB11: 41 | DC11: 33 | DD11: 41 | DE11: 33 | DF11: 41 | DH11: =IF( $C11="Production", IF(MOD(COLUMN(),2)=$DH$3,SUM(E11:F11)-SUM(BF11:BG11),0), F11-BG11) -> 0 | DI11: =IF( $C11="Production", IF(MOD(COLUMN(),2)=$DH$3,SUM(F11:G11)-SUM(BG11:BH11),0), G11-BH11) -> -4.25 | DJ11: =IF( $C11="Production", IF(MOD(COLUMN(),2)=$DH$3,SUM(G11:H11)-SUM(BH11:BI11),0), H11-BI11) -> 0 | DK11: =IF( $C11="Production", IF(MOD(COLUMN(),2)=$DH$3,SUM(H11:I11)-SUM(BI11:BJ11),0), I11-BJ11) -> 0.25 | DL11: =IF( $C11="Production", IF(MOD(COLUMN(),2)=$DH$3,SUM(I11:J11)-SUM(BJ11:BK11),0), J11-BK11) -> 0 | DM11: =IF( $C11="Production", IF(MOD(COLUMN(),2)=$DH$3,SUM(J11:K11)-SUM(BK11:BL11),0), K11-BL11) -> 8.25 | DN11: =IF( $C11="Production", IF(MOD(COLUMN(),2)=$DH$3,SUM(K11:L11)-SUM(BL11:BM11),0), L11-BM11) -> 0 | DO11: =IF( $C11="Production", IF(MOD(COLUMN(),2)=$DH$3,SUM(L11:M11)-SUM(BM11:BN11),0), M11-BN11) -> 8.5 | ... FG11: =IF( $C11="Production", IF(MOD(COLUMN(),2)=$DH$3,SUM(BD11:BE11)-SUM(DE11:DF11),0), BE11-DF11) -> 0 | FH11: =SUM(DH11:FG11) -> 20.5 | FJ11: {=IF($C11="Production", IFERROR(_xlfn.IFS(AND(DH11>0,DH11+SUM(BF11:BG11)<=$FM$3),DH11,AND(DH11>0,DH11+SUM(BF11:BG11)>$FM$3),$FM$3-SUM(BF11:BG11)),0), IFERROR(_xlfn.IFS(AND(DH11>0,DH11+BG11<=$FK$3),DH11,AND(DH11>0,DH11+BG11>$FK$3),0),0) )} -> 0 | FK11: {=IF($C11="Production", IFERROR(_xlfn.IFS(AND(DI11>0,DI11+SUM(BG11:BH11)<=$FM$3),DI11,AND(DI11>0,DI11+SUM(BG11:BH11)>$FM$3),$FM$3-SUM(BG11:BH11)),0), IFERROR(_xlfn.IFS(AND(DI11>0,DI11+BH11<=$FK$3),DI11,AND(DI11>0,DI11+BH11>$FK$3),0),0) )} -> 0 | FL11: {=IF($C11="Production", IFERROR(_xlfn.IFS(AND(DJ11>0,DJ11+SUM(BH11:BI11)<=$FM$3),DJ11,AND(DJ11>0,DJ11+SUM(BH11:BI11)>$FM$3),$FM$3-SUM(BH11:BI11)),0), IFERROR(_xlfn.IFS(AND(DJ11>0,DJ11+BI11<=$FK$3),DJ11,AND(DJ11>0,DJ11+BI11>$FK$3),0),0) )} -> 0 | FM11: {=IF($C11="Production", IFERROR(_xlfn.IFS(AND(DK11>0,DK11+SUM(BI11:BJ11)<=$FM$3),DK11,AND(DK11>0,DK11+SUM(BI11:BJ11)>$FM$3),$FM$3-SUM(BI11:BJ11)),0), IFERROR(_xlfn.IFS(AND(DK11>0,DK11+BJ11<=$FK$3),DK11,AND(DK11>0,DK11+BJ11>$FK$3),0),0) )} -> 0.25 | FN11: {=IF($C11="Production", IFERROR(_xlfn.IFS(AND(DL11>0,DL11+SUM(BJ11:BK11)<=$FM$3),DL11,AND(DL11>0,DL11+SUM(BJ11:BK11)>$FM$3),$FM$3-SUM(BJ11:BK11)),0), IFERROR(_xlfn.IFS(AND(DL11>0,DL11+BK11<=$FK$3),DL11,AND(DL11>0,DL11+BK11>$FK$3),0),0) )} -> 0 | FO11: {=IF($C11="Production", IFERROR(_xlfn.IFS(AND(DM11>0,DM11+SUM(BK11:BL11)<=$FM$3),DM11,AND(DM11>0,DM11+SUM(BK11:BL11)>$FM$3),$FM$3-SUM(BK11:BL11)),0), IFERROR(_xlfn.IFS(AND(DM11>0,DM11+BL11<=$FK$3),DM11,AND(DM11>0,DM11+BL11>$FK$3),0),0) )} -> 8.25 | FP11: {=IF($C11="Production", IFERROR(_xlfn.IFS(AND(DN11>0,DN11+SUM(BL11:BM11)<=$FM$3),DN11,AND(DN11>0,DN11+SUM(BL11:BM11)>$FM$3),$FM$3-SUM(BL11:BM11)),0), IFERROR(_xlfn.IFS(AND(DN11>0,DN11+BM11<=$FK$3),DN11,AND(DN11>0,DN11+BM11>$FK$3),0),0) )} -> 0 | FQ11: {=IF($C11="Production", IFERROR(_xlfn.IFS(AND(DO11>0,DO11+SUM(BM11:BN11)<=$FM$3),DO11,AND(DO11>0,DO11+SUM(BM11:BN11)>$FM$3),$FM$3-SUM(BM11:BN11)),0), IFERROR(_xlfn.IFS(AND(DO11>0,DO11+BN11<=$FK$3),DO11,AND(DO11>0,DO11+BN11>$FK$3),0),0) )} -> 8.5 | ... HI11: {=IF($C11="Production", IFERROR(_xlfn.IFS(AND(FG11>0,FG11+SUM(DE11:DF11)<=$FM$3),FG11,AND(FG11>0,FG11+SUM(DE11:DF11)>$FM$3),$FM$3-SUM(DE11:DF11)),0), IFERROR(_xlfn.IFS(AND(FG11>0,FG11+DF11<=$FK$3),FG11,AND(FG11>0,FG11+DF11>$FK$3),0),0) )} -> 0 | HJ11: =SUM(FJ11:HI11) -> 24.75 | HL11: =IFERROR(IF(FJ11>0,DH11-FJ11,0),0) -> 0 | HM11: =IFERROR(IF(FK11>0,DI11-FK11,0),0) -> 0 | HN11: =IFERROR(IF(FL11>0,DJ11-FL11,0),0) -> 0 | HO11: =IFERROR(IF(FM11>0,DK11-FM11,0),0) -> 0 | HP11: =IFERROR(IF(FN11>0,DL11-FN11,0),0) -> 0 | HQ11: =IFERROR(IF(FO11>0,DM11-FO11,0),0) -> 0 | HR11: =IFERROR(IF(FP11>0,DN11-FP11,0),0) -> 0 | HS11: =IFERROR(IF(FQ11>0,DO11-FQ11,0),0) -> 0 | ... JK11: =IFERROR(IF(HI11>0,FG11-HI11,0),0) -> 0 | JL11: =SUM(HL11:JK11) -> 0 | JO11: =HJ11 -> 24.75 | JP11: =JL11 -> 0 | JQ11: =$JO$4*JO11+$JP$4*JP11 -> 30.9375 | JS11: =SUMIFS(DH11:FG11,DH11:FG11,"<0") -> -4.25 | JU11: =JQ11+JS11 -> 26.6875
B12: ='MODU 2025'!B15 -> BUFFY Stéphanie | C12: ='MODU 2025'!C15 -> Production | D12: ='MODU 2025'!D15 -> 37 | F12: ='MODU 2025'!G15 -> 33 | G12: ='MODU 2025'!H15 -> 41 | H12: ='MODU 2025'!I15 -> 33 | I12: ='MODU 2025'!J15 -> 39.5 | J12: ='MODU 2025'!K15 -> 33 | K12: ='MODU 2025'!L15 -> 42 | L12: ='MODU 2025'!M15 -> 33 | M12: ='MODU 2025'!N15 -> 40 | ... BE12: ='MODU 2025'!BF15 -> 41 | BG12: 33 | BH12: 41 | BI12: 33 | BJ12: 41 | BK12: 33 | BL12: 41 | BM12: 33 | BN12: 41 | BO12: 33 | BP12: 41 | BQ12: 33 | BR12: 41 | BS12: 33 | BT12: 41 | BU12: 33 | BV12: 41 | BW12: 33 | BX12: 41 | BY12: 33 | BZ12: 41 | CA12: 33 | CB12: 41 | CC12: 33 | CD12: 41 | CE12: 33 | CF12: 41 | CG12: 33 | CH12: 41 | CI12: 33 | CJ12: 41 | CK12: 33 | CL12: 41 | CM12: 33 | CN12: 41 | CO12: 33 | CP12: 41 | CQ12: 33 | CR12: 41 | CS12: 33 | CT12: 41 | CU12: 33 | CV12: 41 | CW12: 33 | CX12: 41 | CY12: 33 | CZ12: 41 | DA12: 33 | DB12: 41 | DC12: 33 | DD12: 41 | DE12: 33 | DF12: 41 | DH12: =IF( $C12="Production", IF(MOD(COLUMN(),2)=$DH$3,SUM(E12:F12)-SUM(BF12:BG12),0), F12-BG12) -> 0 | DI12: =IF( $C12="Production", IF(MOD(COLUMN(),2)=$DH$3,SUM(F12:G12)-SUM(BG12:BH12),0), G12-BH12) -> 0 | DJ12: =IF( $C12="Production", IF(MOD(COLUMN(),2)=$DH$3,SUM(G12:H12)-SUM(BH12:BI12),0), H12-BI12) -> 0 | DK12: =IF( $C12="Production", IF(MOD(COLUMN(),2)=$DH$3,SUM(H12:I12)-SUM(BI12:BJ12),0), I12-BJ12) -> -1.5 | DL12: =IF( $C12="Production", IF(MOD(COLUMN(),2)=$DH$3,SUM(I12:J12)-SUM(BJ12:BK12),0), J12-BK12) -> 0 | DM12: =IF( $C12="Production", IF(MOD(COLUMN(),2)=$DH$3,SUM(J12:K12)-SUM(BK12:BL12),0), K12-BL12) -> 1 | DN12: =IF( $C12="Production", IF(MOD(COLUMN(),2)=$DH$3,SUM(K12:L12)-SUM(BL12:BM12),0), L12-BM12) -> 0 | DO12: =IF( $C12="Production", IF(MOD(COLUMN(),2)=$DH$3,SUM(L12:M12)-SUM(BM12:BN12),0), M12-BN12) -> -1 | ... FG12: =IF( $C12="Production", IF(MOD(COLUMN(),2)=$DH$3,SUM(BD12:BE12)-SUM(DE12:DF12),0), BE12-DF12) -> 0 | FH12: =SUM(DH12:FG12) -> 6.25 | FJ12: {=IF($C12="Production", IFERROR(_xlfn.IFS(AND(DH12>0,DH12+SUM(BF12:BG12)<=$FM$3),DH12,AND(DH12>0,DH12+SUM(BF12:BG12)>$FM$3),$FM$3-SUM(BF12:BG12)),0), IFERROR(_xlfn.IFS(AND(DH12>0,DH12+BG12<=$FK$3),DH12,AND(DH12>0,DH12+BG12>$FK$3),0),0) )} -> 0 | FK12: {=IF($C12="Production", IFERROR(_xlfn.IFS(AND(DI12>0,DI12+SUM(BG12:BH12)<=$FM$3),DI12,AND(DI12>0,DI12+SUM(BG12:BH12)>$FM$3),$FM$3-SUM(BG12:BH12)),0), IFERROR(_xlfn.IFS(AND(DI12>0,DI12+BH12<=$FK$3),DI12,AND(DI12>0,DI12+BH12>$FK$3),0),0) )} -> 0 | FL12: {=IF($C12="Production", IFERROR(_xlfn.IFS(AND(DJ12>0,DJ12+SUM(BH12:BI12)<=$FM$3),DJ12,AND(DJ12>0,DJ12+SUM(BH12:BI12)>$FM$3),$FM$3-SUM(BH12:BI12)),0), IFERROR(_xlfn.IFS(AND(DJ12>0,DJ12+BI12<=$FK$3),DJ12,AND(DJ12>0,DJ12+BI12>$FK$3),0),0) )} -> 0 | FM12: {=IF($C12="Production", IFERROR(_xlfn.IFS(AND(DK12>0,DK12+SUM(BI12:BJ12)<=$FM$3),DK12,AND(DK12>0,DK12+SUM(BI12:BJ12)>$FM$3),$FM$3-SUM(BI12:BJ12)),0), IFERROR(_xlfn.IFS(AND(DK12>0,DK12+BJ12<=$FK$3),DK12,AND(DK12>0,DK12+BJ12>$FK$3),0),0) )} -> 0 | FN12: {=IF($C12="Production", IFERROR(_xlfn.IFS(AND(DL12>0,DL12+SUM(BJ12:BK12)<=$FM$3),DL12,AND(DL12>0,DL12+SUM(BJ12:BK12)>$FM$3),$FM$3-SUM(BJ12:BK12)),0), IFERROR(_xlfn.IFS(AND(DL12>0,DL12+BK12<=$FK$3),DL12,AND(DL12>0,DL12+BK12>$FK$3),0),0) )} -> 0 | FO12: {=IF($C12="Production", IFERROR(_xlfn.IFS(AND(DM12>0,DM12+SUM(BK12:BL12)<=$FM$3),DM12,AND(DM12>0,DM12+SUM(BK12:BL12)>$FM$3),$FM$3-SUM(BK12:BL12)),0), IFERROR(_xlfn.IFS(AND(DM12>0,DM12+BL12<=$FK$3),DM12,AND(DM12>0,DM12+BL12>$FK$3),0),0) )} -> 1 | FP12: {=IF($C12="Production", IFERROR(_xlfn.IFS(AND(DN12>0,DN12+SUM(BL12:BM12)<=$FM$3),DN12,AND(DN12>0,DN12+SUM(BL12:BM12)>$FM$3),$FM$3-SUM(BL12:BM12)),0), IFERROR(_xlfn.IFS(AND(DN12>0,DN12+BM12<=$FK$3),DN12,AND(DN12>0,DN12+BM12>$FK$3),0),0) )} -> 0 | FQ12: {=IF($C12="Production", IFERROR(_xlfn.IFS(AND(DO12>0,DO12+SUM(BM12:BN12)<=$FM$3),DO12,AND(DO12>0,DO12+SUM(BM12:BN12)>$FM$3),$FM$3-SUM(BM12:BN12)),0), IFERROR(_xlfn.IFS(AND(DO12>0,DO12+BN12<=$FK$3),DO12,AND(DO12>0,DO12+BN12>$FK$3),0),0) )} -> 0 | ... HI12: {=IF($C12="Production", IFERROR(_xlfn.IFS(AND(FG12>0,FG12+SUM(DE12:DF12)<=$FM$3),FG12,AND(FG12>0,FG12+SUM(DE12:DF12)>$FM$3),$FM$3-SUM(DE12:DF12)),0), IFERROR(_xlfn.IFS(AND(FG12>0,FG12+DF12<=$FK$3),FG12,AND(FG12>0,FG12+DF12>$FK$3),0),0) )} -> 0 | HJ12: =SUM(FJ12:HI12) -> 8.75 | HL12: =IFERROR(IF(FJ12>0,DH12-FJ12,0),0) -> 0 | HM12: =IFERROR(IF(FK12>0,DI12-FK12,0),0) -> 0 | HN12: =IFERROR(IF(FL12>0,DJ12-FL12,0),0) -> 0 | HO12: =IFERROR(IF(FM12>0,DK12-FM12,0),0) -> 0 | HP12: =IFERROR(IF(FN12>0,DL12-FN12,0),0) -> 0 | HQ12: =IFERROR(IF(FO12>0,DM12-FO12,0),0) -> 0 | HR12: =IFERROR(IF(FP12>0,DN12-FP12,0),0) -> 0 | HS12: =IFERROR(IF(FQ12>0,DO12-FQ12,0),0) -> 0 | ... JK12: =IFERROR(IF(HI12>0,FG12-HI12,0),0) -> 0 | JL12: =SUM(HL12:JK12) -> 0 | JO12: =HJ12 -> 8.75 | JP12: =JL12 -> 0 | JQ12: =$JO$4*JO12+$JP$4*JP12 -> 10.9375 | JS12: =SUMIFS(DH12:FG12,DH12:FG12,"<0") -> -2.5 | JU12: =JQ12+JS12 -> 8.4375
B13: ='MODU 2025'!B16 -> BUISSON Cassandra | C13: ='MODU 2025'!C16 -> Production | D13: 28 | F13: ='MODU 2025'!G16 -> 37 | G13: ='MODU 2025'!H16 -> 41 | H13: ='MODU 2025'!I16 -> 29.25 | I13: ='MODU 2025'!J16 -> 41 | J13: ='MODU 2025'!K16 -> 33 | K13: ='MODU 2025'!L16 -> 41 | L13: ='MODU 2025'!M16 -> 33 | M13: ='MODU 2025'!N16 -> 41.25 | ... BE13: ='MODU 2025'!BF16 -> 36 | BG13: 33 | BH13: 41 | BI13: 33 | BJ13: 41 | BK13: 33 | BL13: 41 | BM13: 33 | BN13: 41 | BO13: 20 | BP13: 36 | BQ13: 20 | BR13: 36 | BS13: 20 | BT13: 36 | BU13: 20 | BV13: 36 | BW13: 20 | BX13: 36 | BY13: 20 | BZ13: 36 | CA13: 20 | CB13: 36 | CC13: 20 | CD13: 36 | CE13: 20 | CF13: 36 | CG13: 20 | CH13: 36 | CI13: 20 | CJ13: 36 | CK13: 20 | CL13: 36 | CM13: 20 | CN13: 36 | CO13: 20 | CP13: 36 | CQ13: 20 | CR13: 36 | CS13: 20 | CT13: 36 | CU13: 20 | CV13: 36 | CW13: 20 | CX13: 36 | CY13: 20 | CZ13: 36 | DA13: 20 | DB13: 36 | DC13: 20 | DD13: 36 | DE13: 20 | DF13: 36 | DH13: =IF( $C13="Production", IF(MOD(COLUMN(),2)=$DH$3,SUM(E13:F13)-SUM(BF13:BG13),0), F13-BG13) -> 0 | DI13: =IF( $C13="Production", IF(MOD(COLUMN(),2)=$DH$3,SUM(F13:G13)-SUM(BG13:BH13),0), G13-BH13) -> 4 | DJ13: =IF( $C13="Production", IF(MOD(COLUMN(),2)=$DH$3,SUM(G13:H13)-SUM(BH13:BI13),0), H13-BI13) -> 0 | DK13: =IF( $C13="Production", IF(MOD(COLUMN(),2)=$DH$3,SUM(H13:I13)-SUM(BI13:BJ13),0), I13-BJ13) -> -3.75 | DL13: =IF( $C13="Production", IF(MOD(COLUMN(),2)=$DH$3,SUM(I13:J13)-SUM(BJ13:BK13),0), J13-BK13) -> 0 | DM13: =IF( $C13="Production", IF(MOD(COLUMN(),2)=$DH$3,SUM(J13:K13)-SUM(BK13:BL13),0), K13-BL13) -> 0 | DN13: =IF( $C13="Production", IF(MOD(COLUMN(),2)=$DH$3,SUM(K13:L13)-SUM(BL13:BM13),0), L13-BM13) -> 0 | DO13: =IF( $C13="Production", IF(MOD(COLUMN(),2)=$DH$3,SUM(L13:M13)-SUM(BM13:BN13),0), M13-BN13) -> 0.25 | ... FG13: =IF( $C13="Production", IF(MOD(COLUMN(),2)=$DH$3,SUM(BD13:BE13)-SUM(DE13:DF13),0), BE13-DF13) -> 0 | FH13: =SUM(DH13:FG13) -> 0.5 | FJ13: {=IF($C13="Production", IFERROR(_xlfn.IFS(AND(DH13>0,DH13+SUM(BF13:BG13)<=$FM$3),DH13,AND(DH13>0,DH13+SUM(BF13:BG13)>$FM$3),$FM$3-SUM(BF13:BG13)),0), IFERROR(_xlfn.IFS(AND(DH13>0,DH13+BG13<=$FK$3),DH13,AND(DH13>0,DH13+BG13>$FK$3),0),0) )} -> 0 | FK13: {=IF($C13="Production", IFERROR(_xlfn.IFS(AND(DI13>0,DI13+SUM(BG13:BH13)<=$FM$3),DI13,AND(DI13>0,DI13+SUM(BG13:BH13)>$FM$3),$FM$3-SUM(BG13:BH13)),0), IFERROR(_xlfn.IFS(AND(DI13>0,DI13+BH13<=$FK$3),DI13,AND(DI13>0,DI13+BH13>$FK$3),0),0) )} -> 4 | FL13: {=IF($C13="Production", IFERROR(_xlfn.IFS(AND(DJ13>0,DJ13+SUM(BH13:BI13)<=$FM$3),DJ13,AND(DJ13>0,DJ13+SUM(BH13:BI13)>$FM$3),$FM$3-SUM(BH13:BI13)),0), IFERROR(_xlfn.IFS(AND(DJ13>0,DJ13+BI13<=$FK$3),DJ13,AND(DJ13>0,DJ13+BI13>$FK$3),0),0) )} -> 0 | FM13: {=IF($C13="Production", IFERROR(_xlfn.IFS(AND(DK13>0,DK13+SUM(BI13:BJ13)<=$FM$3),DK13,AND(DK13>0,DK13+SUM(BI13:BJ13)>$FM$3),$FM$3-SUM(BI13:BJ13)),0), IFERROR(_xlfn.IFS(AND(DK13>0,DK13+BJ13<=$FK$3),DK13,AND(DK13>0,DK13+BJ13>$FK$3),0),0) )} -> 0 | FN13: {=IF($C13="Production", IFERROR(_xlfn.IFS(AND(DL13>0,DL13+SUM(BJ13:BK13)<=$FM$3),DL13,AND(DL13>0,DL13+SUM(BJ13:BK13)>$FM$3),$FM$3-SUM(BJ13:BK13)),0), IFERROR(_xlfn.IFS(AND(DL13>0,DL13+BK13<=$FK$3),DL13,AND(DL13>0,DL13+BK13>$FK$3),0),0) )} -> 0 | FO13: {=IF($C13="Production", IFERROR(_xlfn.IFS(AND(DM13>0,DM13+SUM(BK13:BL13)<=$FM$3),DM13,AND(DM13>0,DM13+SUM(BK13:BL13)>$FM$3),$FM$3-SUM(BK13:BL13)),0), IFERROR(_xlfn.IFS(AND(DM13>0,DM13+BL13<=$FK$3),DM13,AND(DM13>0,DM13+BL13>$FK$3),0),0) )} -> 0 | FP13: {=IF($C13="Production", IFERROR(_xlfn.IFS(AND(DN13>0,DN13+SUM(BL13:BM13)<=$FM$3),DN13,AND(DN13>0,DN13+SUM(BL13:BM13)>$FM$3),$FM$3-SUM(BL13:BM13)),0), IFERROR(_xlfn.IFS(AND(DN13>0,DN13+BM13<=$FK$3),DN13,AND(DN13>0,DN13+BM13>$FK$3),0),0) )} -> 0 | FQ13: {=IF($C13="Production", IFERROR(_xlfn.IFS(AND(DO13>0,DO13+SUM(BM13:BN13)<=$FM$3),DO13,AND(DO13>0,DO13+SUM(BM13:BN13)>$FM$3),$FM$3-SUM(BM13:BN13)),0), IFERROR(_xlfn.IFS(AND(DO13>0,DO13+BN13<=$FK$3),DO13,AND(DO13>0,DO13+BN13>$FK$3),0),0) )} -> 0.25 | ... HI13: {=IF($C13="Production", IFERROR(_xlfn.IFS(AND(FG13>0,FG13+SUM(DE13:DF13)<=$FM$3),FG13,AND(FG13>0,FG13+SUM(DE13:DF13)>$FM$3),$FM$3-SUM(DE13:DF13)),0), IFERROR(_xlfn.IFS(AND(FG13>0,FG13+DF13<=$FK$3),FG13,AND(FG13>0,FG13+DF13>$FK$3),0),0) )} -> 0 | HJ13: =SUM(FJ13:HI13) -> 4.25 | HL13: =IFERROR(IF(FJ13>0,DH13-FJ13,0),0) -> 0 | HM13: =IFERROR(IF(FK13>0,DI13-FK13,0),0) -> 0 | HN13: =IFERROR(IF(FL13>0,DJ13-FL13,0),0) -> 0 | HO13: =IFERROR(IF(FM13>0,DK13-FM13,0),0) -> 0 | HP13: =IFERROR(IF(FN13>0,DL13-FN13,0),0) -> 0 | HQ13: =IFERROR(IF(FO13>0,DM13-FO13,0),0) -> 0 | HR13: =IFERROR(IF(FP13>0,DN13-FP13,0),0) -> 0 | HS13: =IFERROR(IF(FQ13>0,DO13-FQ13,0),0) -> 0 | ... JK13: =IFERROR(IF(HI13>0,FG13-HI13,0),0) -> 0 | JL13: =SUM(HL13:JK13) -> 0 | JO13: =HJ13 -> 4.25 | JP13: =JL13 -> 0 | JQ13: =$JO$4*JO13+$JP$4*JP13 -> 5.3125 | JS13: =SUMIFS(DH13:FG13,DH13:FG13,"<0") -> -3.75 | JU13: =JQ13+JS13 -> 1.5625
B14: ='MODU 2025'!B17 -> CANU Jason | C14: ='MODU 2025'!C17 -> Production | D14: ='MODU 2025'!D17 -> 37 | F14: ='MODU 2025'!G17 -> 33 | G14: ='MODU 2025'!H17 -> 41 | H14: ='MODU 2025'!I17 -> 33 | I14: ='MODU 2025'!J17 -> 41 | J14: ='MODU 2025'!K17 -> 33 | K14: ='MODU 2025'!L17 -> 32.75 | L14: ='MODU 2025'!M17 -> 37.5 | M14: ='MODU 2025'!N17 -> 41 | ... BE14: ='MODU 2025'!BF17 -> 41 | BG14: 33 | BH14: 41 | BI14: 33 | BJ14: 41 | BK14: 33 | BL14: 41 | BM14: 33 | BN14: 41 | BO14: 33 | BP14: 41 | BQ14: 33 | BR14: 41 | BS14: 33 | BT14: 41 | BU14: 33 | BV14: 41 | BW14: 33 | BX14: 41 | BY14: 33 | BZ14: 41 | CA14: 33 | CB14: 41 | CC14: 33 | CD14: 41 | CE14: 33 | CF14: 41 | CG14: 33 | CH14: 41 | CI14: 33 | CJ14: 41 | CK14: 33 | CL14: 41 | CM14: 33 | CN14: 41 | CO14: 33 | CP14: 41 | CQ14: 33 | CR14: 41 | CS14: 33 | CT14: 41 | CU14: 33 | CV14: 41 | CW14: 33 | CX14: 41 | CY14: 33 | CZ14: 41 | DA14: 33 | DB14: 41 | DC14: 33 | DD14: 41 | DE14: 33 | DF14: 41 | DH14: =IF( $C14="Production", IF(MOD(COLUMN(),2)=$DH$3,SUM(E14:F14)-SUM(BF14:BG14),0), F14-BG14) -> 0 | DI14: =IF( $C14="Production", IF(MOD(COLUMN(),2)=$DH$3,SUM(F14:G14)-SUM(BG14:BH14),0), G14-BH14) -> 0 | DJ14: =IF( $C14="Production", IF(MOD(COLUMN(),2)=$DH$3,SUM(G14:H14)-SUM(BH14:BI14),0), H14-BI14) -> 0 | DK14: =IF( $C14="Production", IF(MOD(COLUMN(),2)=$DH$3,SUM(H14:I14)-SUM(BI14:BJ14),0), I14-BJ14) -> 0 | DL14: =IF( $C14="Production", IF(MOD(COLUMN(),2)=$DH$3,SUM(I14:J14)-SUM(BJ14:BK14),0), J14-BK14) -> 0 | DM14: =IF( $C14="Production", IF(MOD(COLUMN(),2)=$DH$3,SUM(J14:K14)-SUM(BK14:BL14),0), K14-BL14) -> -8.25 | DN14: =IF( $C14="Production", IF(MOD(COLUMN(),2)=$DH$3,SUM(K14:L14)-SUM(BL14:BM14),0), L14-BM14) -> 0 | DO14: =IF( $C14="Production", IF(MOD(COLUMN(),2)=$DH$3,SUM(L14:M14)-SUM(BM14:BN14),0), M14-BN14) -> 4.5 | ... FG14: =IF( $C14="Production", IF(MOD(COLUMN(),2)=$DH$3,SUM(BD14:BE14)-SUM(DE14:DF14),0), BE14-DF14) -> 0 | FH14: =SUM(DH14:FG14) -> 1 | FJ14: {=IF($C14="Production", IFERROR(_xlfn.IFS(AND(DH14>0,DH14+SUM(BF14:BG14)<=$FM$3),DH14,AND(DH14>0,DH14+SUM(BF14:BG14)>$FM$3),$FM$3-SUM(BF14:BG14)),0), IFERROR(_xlfn.IFS(AND(DH14>0,DH14+BG14<=$FK$3),DH14,AND(DH14>0,DH14+BG14>$FK$3),0),0) )} -> 0 | FK14: {=IF($C14="Production", IFERROR(_xlfn.IFS(AND(DI14>0,DI14+SUM(BG14:BH14)<=$FM$3),DI14,AND(DI14>0,DI14+SUM(BG14:BH14)>$FM$3),$FM$3-SUM(BG14:BH14)),0), IFERROR(_xlfn.IFS(AND(DI14>0,DI14+BH14<=$FK$3),DI14,AND(DI14>0,DI14+BH14>$FK$3),0),0) )} -> 0 | FL14: {=IF($C14="Production", IFERROR(_xlfn.IFS(AND(DJ14>0,DJ14+SUM(BH14:BI14)<=$FM$3),DJ14,AND(DJ14>0,DJ14+SUM(BH14:BI14)>$FM$3),$FM$3-SUM(BH14:BI14)),0), IFERROR(_xlfn.IFS(AND(DJ14>0,DJ14+BI14<=$FK$3),DJ14,AND(DJ14>0,DJ14+BI14>$FK$3),0),0) )} -> 0 | FM14: {=IF($C14="Production", IFERROR(_xlfn.IFS(AND(DK14>0,DK14+SUM(BI14:BJ14)<=$FM$3),DK14,AND(DK14>0,DK14+SUM(BI14:BJ14)>$FM$3),$FM$3-SUM(BI14:BJ14)),0), IFERROR(_xlfn.IFS(AND(DK14>0,DK14+BJ14<=$FK$3),DK14,AND(DK14>0,DK14+BJ14>$FK$3),0),0) )} -> 0 | FN14: {=IF($C14="Production", IFERROR(_xlfn.IFS(AND(DL14>0,DL14+SUM(BJ14:BK14)<=$FM$3),DL14,AND(DL14>0,DL14+SUM(BJ14:BK14)>$FM$3),$FM$3-SUM(BJ14:BK14)),0), IFERROR(_xlfn.IFS(AND(DL14>0,DL14+BK14<=$FK$3),DL14,AND(DL14>0,DL14+BK14>$FK$3),0),0) )} -> 0 | FO14: {=IF($C14="Production", IFERROR(_xlfn.IFS(AND(DM14>0,DM14+SUM(BK14:BL14)<=$FM$3),DM14,AND(DM14>0,DM14+SUM(BK14:BL14)>$FM$3),$FM$3-SUM(BK14:BL14)),0), IFERROR(_xlfn.IFS(AND(DM14>0,DM14+BL14<=$FK$3),DM14,AND(DM14>0,DM14+BL14>$FK$3),0),0) )} -> 0 | FP14: {=IF($C14="Production", IFERROR(_xlfn.IFS(AND(DN14>0,DN14+SUM(BL14:BM14)<=$FM$3),DN14,AND(DN14>0,DN14+SUM(BL14:BM14)>$FM$3),$FM$3-SUM(BL14:BM14)),0), IFERROR(_xlfn.IFS(AND(DN14>0,DN14+BM14<=$FK$3),DN14,AND(DN14>0,DN14+BM14>$FK$3),0),0) )} -> 0 | FQ14: {=IF($C14="Production", IFERROR(_xlfn.IFS(AND(DO14>0,DO14+SUM(BM14:BN14)<=$FM$3),DO14,AND(DO14>0,DO14+SUM(BM14:BN14)>$FM$3),$FM$3-SUM(BM14:BN14)),0), IFERROR(_xlfn.IFS(AND(DO14>0,DO14+BN14<=$FK$3),DO14,AND(DO14>0,DO14+BN14>$FK$3),0),0) )} -> 4.5 | ... HI14: {=IF($C14="Production", IFERROR(_xlfn.IFS(AND(FG14>0,FG14+SUM(DE14:DF14)<=$FM$3),FG14,AND(FG14>0,FG14+SUM(DE14:DF14)>$FM$3),$FM$3-SUM(DE14:DF14)),0), IFERROR(_xlfn.IFS(AND(FG14>0,FG14+DF14<=$FK$3),FG14,AND(FG14>0,FG14+DF14>$FK$3),0),0) )} -> 0 | HJ14: =SUM(FJ14:HI14) -> 9.25 | HL14: =IFERROR(IF(FJ14>0,DH14-FJ14,0),0) -> 0 | HM14: =IFERROR(IF(FK14>0,DI14-FK14,0),0) -> 0 | HN14: =IFERROR(IF(FL14>0,DJ14-FL14,0),0) -> 0 | HO14: =IFERROR(IF(FM14>0,DK14-FM14,0),0) -> 0 | HP14: =IFERROR(IF(FN14>0,DL14-FN14,0),0) -> 0 | HQ14: =IFERROR(IF(FO14>0,DM14-FO14,0),0) -> 0 | HR14: =IFERROR(IF(FP14>0,DN14-FP14,0),0) -> 0 | HS14: =IFERROR(IF(FQ14>0,DO14-FQ14,0),0) -> 0 | ... JK14: =IFERROR(IF(HI14>0,FG14-HI14,0),0) -> 0 | JL14: =SUM(HL14:JK14) -> 0 | JO14: =HJ14 -> 9.25 | JP14: =JL14 -> 0 | JQ14: =$JO$4*JO14+$JP$4*JP14 -> 11.5625 | JS14: =SUMIFS(DH14:FG14,DH14:FG14,"<0") -> -8.25 | JU14: =JQ14+JS14 -> 3.3125
B15: ='MODU 2025'!B18 -> COCHET Mélina | C15: ='MODU 2025'!C18 -> Logistique | D15: ='MODU 2025'!D18 -> 39 | F15: ='MODU 2025'!G18 -> 40 | G15: ='MODU 2025'!H18 -> 40 | H15: ='MODU 2025'!I18 -> 40.5 | I15: ='MODU 2025'!J18 -> 39.5 | J15: ='MODU 2025'!K18 -> 39.5 | K15: ='MODU 2025'!L18 -> 39.25 | L15: ='MODU 2025'!M18 -> 41.75 | M15: ='MODU 2025'!N18 -> 40 | ... BE15: ='MODU 2025'!BF18 -> 39 | BG15: 39 | BH15: 39 | BI15: 39 | BJ15: 39 | BK15: 39 | BL15: 39 | BM15: 39 | BN15: 39 | BO15: 39 | BP15: 39 | BQ15: 39 | BR15: 39 | BS15: 39 | BT15: 39 | BU15: 39 | BV15: 39 | BW15: 39 | BX15: 39 | BY15: 39 | BZ15: 39 | CA15: 39 | CB15: 39 | CC15: 39 | CD15: 39 | CE15: 39 | CF15: 39 | CG15: 39 | CH15: 39 | CI15: 39 | CJ15: 39 | CK15: 39 | CL15: 39 | CM15: 39 | CN15: 39 | CO15: 39 | CP15: 39 | CQ15: 39 | CR15: 39 | CS15: 39 | CT15: 39 | CU15: 39 | CV15: 39 | CW15: 39 | CX15: 39 | CY15: 39 | CZ15: 39 | DA15: 39 | DB15: 39 | DC15: 39 | DD15: 39 | DE15: 39 | DF15: 39 | DH15: =IF( $C15="Production", IF(MOD(COLUMN(),2)=$DH$3,SUM(E15:F15)-SUM(BF15:BG15),0), F15-BG15) -> 1 | DI15: =IF( $C15="Production", IF(MOD(COLUMN(),2)=$DH$3,SUM(F15:G15)-SUM(BG15:BH15),0), G15-BH15) -> 1 | DJ15: =IF( $C15="Production", IF(MOD(COLUMN(),2)=$DH$3,SUM(G15:H15)-SUM(BH15:BI15),0), H15-BI15) -> 1.5 | DK15: =IF( $C15="Production", IF(MOD(COLUMN(),2)=$DH$3,SUM(H15:I15)-SUM(BI15:BJ15),0), I15-BJ15) -> 0.5 | DL15: =IF( $C15="Production", IF(MOD(COLUMN(),2)=$DH$3,SUM(I15:J15)-SUM(BJ15:BK15),0), J15-BK15) -> 0.5 | DM15: =IF( $C15="Production", IF(MOD(COLUMN(),2)=$DH$3,SUM(J15:K15)-SUM(BK15:BL15),0), K15-BL15) -> 0.25 | DN15: =IF( $C15="Production", IF(MOD(COLUMN(),2)=$DH$3,SUM(K15:L15)-SUM(BL15:BM15),0), L15-BM15) -> 2.75 | DO15: =IF( $C15="Production", IF(MOD(COLUMN(),2)=$DH$3,SUM(L15:M15)-SUM(BM15:BN15),0), M15-BN15) -> 1 | ... FG15: =IF( $C15="Production", IF(MOD(COLUMN(),2)=$DH$3,SUM(BD15:BE15)-SUM(DE15:DF15),0), BE15-DF15) -> 0 | FH15: =SUM(DH15:FG15) -> 8.5 | FJ15: {=IF($C15="Production", IFERROR(_xlfn.IFS(AND(DH15>0,DH15+SUM(BF15:BG15)<=$FM$3),DH15,AND(DH15>0,DH15+SUM(BF15:BG15)>$FM$3),$FM$3-SUM(BF15:BG15)),0), IFERROR(_xlfn.IFS(AND(DH15>0,DH15+BG15<=$FK$3),DH15,AND(DH15>0,DH15+BG15>$FK$3),0),0) )} -> 1 | FK15: {=IF($C15="Production", IFERROR(_xlfn.IFS(AND(DI15>0,DI15+SUM(BG15:BH15)<=$FM$3),DI15,AND(DI15>0,DI15+SUM(BG15:BH15)>$FM$3),$FM$3-SUM(BG15:BH15)),0), IFERROR(_xlfn.IFS(AND(DI15>0,DI15+BH15<=$FK$3),DI15,AND(DI15>0,DI15+BH15>$FK$3),0),0) )} -> 1 | FL15: {=IF($C15="Production", IFERROR(_xlfn.IFS(AND(DJ15>0,DJ15+SUM(BH15:BI15)<=$FM$3),DJ15,AND(DJ15>0,DJ15+SUM(BH15:BI15)>$FM$3),$FM$3-SUM(BH15:BI15)),0), IFERROR(_xlfn.IFS(AND(DJ15>0,DJ15+BI15<=$FK$3),DJ15,AND(DJ15>0,DJ15+BI15>$FK$3),0),0) )} -> 1.5 | FM15: {=IF($C15="Production", IFERROR(_xlfn.IFS(AND(DK15>0,DK15+SUM(BI15:BJ15)<=$FM$3),DK15,AND(DK15>0,DK15+SUM(BI15:BJ15)>$FM$3),$FM$3-SUM(BI15:BJ15)),0), IFERROR(_xlfn.IFS(AND(DK15>0,DK15+BJ15<=$FK$3),DK15,AND(DK15>0,DK15+BJ15>$FK$3),0),0) )} -> 0.5 | FN15: {=IF($C15="Production", IFERROR(_xlfn.IFS(AND(DL15>0,DL15+SUM(BJ15:BK15)<=$FM$3),DL15,AND(DL15>0,DL15+SUM(BJ15:BK15)>$FM$3),$FM$3-SUM(BJ15:BK15)),0), IFERROR(_xlfn.IFS(AND(DL15>0,DL15+BK15<=$FK$3),DL15,AND(DL15>0,DL15+BK15>$FK$3),0),0) )} -> 0.5 | FO15: {=IF($C15="Production", IFERROR(_xlfn.IFS(AND(DM15>0,DM15+SUM(BK15:BL15)<=$FM$3),DM15,AND(DM15>0,DM15+SUM(BK15:BL15)>$FM$3),$FM$3-SUM(BK15:BL15)),0), IFERROR(_xlfn.IFS(AND(DM15>0,DM15+BL15<=$FK$3),DM15,AND(DM15>0,DM15+BL15>$FK$3),0),0) )} -> 0.25 | FP15: {=IF($C15="Production", IFERROR(_xlfn.IFS(AND(DN15>0,DN15+SUM(BL15:BM15)<=$FM$3),DN15,AND(DN15>0,DN15+SUM(BL15:BM15)>$FM$3),$FM$3-SUM(BL15:BM15)),0), IFERROR(_xlfn.IFS(AND(DN15>0,DN15+BM15<=$FK$3),DN15,AND(DN15>0,DN15+BM15>$FK$3),0),0) )} -> 2.75 | FQ15: {=IF($C15="Production", IFERROR(_xlfn.IFS(AND(DO15>0,DO15+SUM(BM15:BN15)<=$FM$3),DO15,AND(DO15>0,DO15+SUM(BM15:BN15)>$FM$3),$FM$3-SUM(BM15:BN15)),0), IFERROR(_xlfn.IFS(AND(DO15>0,DO15+BN15<=$FK$3),DO15,AND(DO15>0,DO15+BN15>$FK$3),0),0) )} -> 1 | ... HI15: {=IF($C15="Production", IFERROR(_xlfn.IFS(AND(FG15>0,FG15+SUM(DE15:DF15)<=$FM$3),FG15,AND(FG15>0,FG15+SUM(DE15:DF15)>$FM$3),$FM$3-SUM(DE15:DF15)),0), IFERROR(_xlfn.IFS(AND(FG15>0,FG15+DF15<=$FK$3),FG15,AND(FG15>0,FG15+DF15>$FK$3),0),0) )} -> 0 | HJ15: =SUM(FJ15:HI15) -> 8.5 | HL15: =IFERROR(IF(FJ15>0,DH15-FJ15,0),0) -> 0 | HM15: =IFERROR(IF(FK15>0,DI15-FK15,0),0) -> 0 | HN15: =IFERROR(IF(FL15>0,DJ15-FL15,0),0) -> 0 | HO15: =IFERROR(IF(FM15>0,DK15-FM15,0),0) -> 0 | HP15: =IFERROR(IF(FN15>0,DL15-FN15,0),0) -> 0 | HQ15: =IFERROR(IF(FO15>0,DM15-FO15,0),0) -> 0 | HR15: =IFERROR(IF(FP15>0,DN15-FP15,0),0) -> 0 | HS15: =IFERROR(IF(FQ15>0,DO15-FQ15,0),0) -> 0 | ... JK15: =IFERROR(IF(HI15>0,FG15-HI15,0),0) -> 0 | JL15: =SUM(HL15:JK15) -> 0 | JO15: =HJ15 -> 8.5 | JP15: =JL15 -> 0 | JQ15: =$JO$4*JO15+$JP$4*JP15 -> 10.625 | JS15: =SUMIFS(DH15:FG15,DH15:FG15,"<0") -> 0 | JU15: =JQ15+JS15 -> 10.625
